<?xml version="1.0" ?>
<!-- =================================================================================== -->
<!-- |    This document was autogenerated by xacro from /home/VICOMTECH/mojer/catkin_ws/src/acroba_ros/acroba_resources/urdf/cabka_robot_camera.xacro | -->
<!-- |    EDITING THIS FILE BY HAND IS NOT RECOMMENDED                                 | -->
<!-- =================================================================================== -->
<robot name="cabka_robot1">
  <!-- colours based on RAL values given in "FAQ - Colours of robot and robot
       controller", version "KUKA.Tifs | 2010-01-21 |YM| DefaultColorsRobotAndController.doc",
       downloaded 2015-07-18 from
       http://www.kuka.be/main/cservice/faqs/hardware/DefaultColorsRobotAndController.pdf

       all RAL colours converted using http://www.visual-graphics.de/en/customer-care/ral-colours
  -->
  <link name="base_link">
    <visual>
      <origin rpy="0 0 0" xyz="0 0 0.0"/>
      <geometry>
        <mesh filename="package://acroba_resources/meshes/kuka_kr20/base.stl" scale="0.001 0.001 0.001"/>
      </geometry>
      <material name="">
        <color rgba="0.054901960784313725 0.054901960784313725 0.06274509803921569 1.0"/>
      </material>
    </visual>
    <collision>
      <origin rpy="0 0 0" xyz="0 0 0.0"/>
      <geometry>
        <mesh filename="package://acroba_resources/meshes/kuka_kr20/base_convex.stl" scale="0.001 0.001 0.001"/>
      </geometry>
    </collision>
    <inertial>
      <mass value="1"/>
      <inertia ixx="0.08333333333333333" ixy="0.0" ixz="0.0" iyy="0.08333333333333333" iyz="0.0" izz="0.08333333333333333"/>
    </inertial>
  </link>
  <!--z coord from cad-->
  <link name="link_1">
    <visual>
      <origin rpy="0 0 0" xyz="0 0 -0.250"/>
      <geometry>
        <mesh filename="package://acroba_resources/meshes/kuka_kr20/link1.stl" scale="0.001 0.001 0.001"/>
      </geometry>
      <material name="">
        <color rgba="0.9647058823529412 0.47058823529411764 0.1568627450980392 1.0"/>
      </material>
    </visual>
    <collision>
      <origin rpy="0 0 0" xyz="0 0 -0.250"/>
      <geometry>
        <mesh filename="package://acroba_resources/meshes/kuka_kr20/link1_convex.stl" scale="0.001 0.001 0.001"/>
      </geometry>
    </collision>
    <inertial>
      <mass value="1"/>
      <inertia ixx="0.08333333333333333" ixy="0.0" ixz="0.0" iyy="0.08333333333333333" iyz="0.0" izz="0.08333333333333333"/>
    </inertial>
  </link>
  <!--y coord from cad-->
  <link name="link_2">
    <visual>
      <origin rpy="0 0 0" xyz="-0.16 0.0889 -0.52"/>
      <geometry>
        <mesh filename="package://acroba_resources/meshes/kuka_kr20/link2.stl" scale="0.001 0.001 0.001"/>
      </geometry>
      <material name="">
        <color rgba="0.9647058823529412 0.47058823529411764 0.1568627450980392 1.0"/>
      </material>
    </visual>
    <collision>
      <origin rpy="0 0 0" xyz="-0.16 0.0889 -0.52"/>
      <geometry>
        <mesh filename="package://acroba_resources/meshes/kuka_kr20/link2_convex.stl" scale="0.001 0.001 0.001"/>
      </geometry>
    </collision>
    <inertial>
      <mass value="1"/>
      <inertia ixx="0.08333333333333333" ixy="0.0" ixz="0.0" iyy="0.08333333333333333" iyz="0.0" izz="0.08333333333333333"/>
    </inertial>
  </link>
  <!-- y coord from cad-->
  <link name="link_3">
    <visual>
      <origin rpy="0 0 0" xyz="-0.16 0.0978 -1.30"/>
      <geometry>
        <mesh filename="package://acroba_resources/meshes/kuka_kr20/link3.stl" scale="0.001 0.001 0.001"/>
      </geometry>
      <material name="">
        <color rgba="0.9647058823529412 0.47058823529411764 0.1568627450980392 1.0"/>
      </material>
    </visual>
    <collision>
      <origin rpy="0 0 0" xyz="-0.16 0.0978 -1.30"/>
      <geometry>
        <mesh filename="package://acroba_resources/meshes/kuka_kr20/link3_convex.stl" scale="0.001 0.001 0.001"/>
      </geometry>
    </collision>
    <inertial>
      <mass value="1"/>
      <inertia ixx="0.08333333333333333" ixy="0.0" ixz="0.0" iyy="0.08333333333333333" iyz="0.0" izz="0.08333333333333333"/>
    </inertial>
  </link>
  <!-- y coord from cad-->
  <link name="link_3_1">
    <visual>
      <origin rpy="0 0 0" xyz="-0.16 0.006 -1.30"/>
      <geometry>
        <mesh filename="package://acroba_resources/meshes/kuka_kr20/link3_1.stl" scale="0.001 0.001 0.001"/>
      </geometry>
      <material name="">
        <color rgba="0.9647058823529412 0.47058823529411764 0.1568627450980392 1.0"/>
      </material>
    </visual>
    <collision>
      <origin rpy="0 0 0" xyz="-0.16 0.006 -1.30"/>
      <geometry>
        <mesh filename="package://acroba_resources/meshes/kuka_kr20/link3_1_convex.stl" scale="0.001 0.001 0.001"/>
      </geometry>
    </collision>
    <inertial>
      <mass value="1"/>
      <inertia ixx="0.08333333333333333" ixy="0.0" ixz="0.0" iyy="0.08333333333333333" iyz="0.0" izz="0.08333333333333333"/>
    </inertial>
  </link>
  <link name="link_4">
    <visual>
      <origin rpy="0 0 0" xyz="-0.46 0 -1.45"/>
      <geometry>
        <mesh filename="package://acroba_resources/meshes/kuka_kr20/link4.stl" scale="0.001 0.001 0.001"/>
      </geometry>
      <material name="">
        <color rgba="0.9647058823529412 0.47058823529411764 0.1568627450980392 1.0"/>
      </material>
    </visual>
    <collision>
      <origin rpy="0 0 0" xyz="-0.46 0 -1.45"/>
      <geometry>
        <mesh filename="package://acroba_resources/meshes/kuka_kr20/link4_convex.stl" scale="0.001 0.001 0.001"/>
      </geometry>
    </collision>
    <inertial>
      <mass value="1"/>
      <inertia ixx="0.08333333333333333" ixy="0.0" ixz="0.0" iyy="0.08333333333333333" iyz="0.0" izz="0.08333333333333333"/>
    </inertial>
  </link>
  <link name="link_5">
    <visual>
      <origin rpy="0 0 0" xyz="-0.87 0 -1.45"/>
      <geometry>
        <mesh filename="package://acroba_resources/meshes/kuka_kr20/link5.stl" scale="0.001 0.001 0.001"/>
      </geometry>
      <material name="">
        <color rgba="0.9647058823529412 0.47058823529411764 0.1568627450980392 1.0"/>
      </material>
    </visual>
    <collision>
      <origin rpy="0 0 0" xyz="-0.87 0 -1.45"/>
      <geometry>
        <mesh filename="package://acroba_resources/meshes/kuka_kr20/link5_convex.stl" scale="0.001 0.001 0.001"/>
      </geometry>
    </collision>
    <inertial>
      <mass value="1"/>
      <inertia ixx="0.08333333333333333" ixy="0.0" ixz="0.0" iyy="0.08333333333333333" iyz="0.0" izz="0.08333333333333333"/>
    </inertial>
  </link>
  <link name="link_6">
    <visual>
      <origin rpy="0 0 0" xyz="-1.02 0 -1.45"/>
      <geometry>
        <mesh filename="package://acroba_resources/meshes/kuka_kr20/link6.stl" scale="0.001 0.001 0.001"/>
      </geometry>
      <material name="">
        <color rgba="0.9647058823529412 0.47058823529411764 0.1568627450980392 1.0"/>
      </material>
    </visual>
    <collision>
      <origin rpy="0 0 0" xyz="-1.02 0 -1.45"/>
      <geometry>
        <mesh filename="package://acroba_resources/meshes/kuka_kr20/link6_convex.stl" scale="0.001 0.001 0.001"/>
      </geometry>
    </collision>
    <inertial>
      <mass value="1"/>
      <inertia ixx="0.08333333333333333" ixy="0.0" ixz="0.0" iyy="0.08333333333333333" iyz="0.0" izz="0.08333333333333333"/>
    </inertial>
  </link>
  <link name="link_7">
    <visual>
      <origin rpy="0 0 0" xyz="-1.173 0 -1.45"/>
      <geometry>
        <mesh filename="package://acroba_resources/meshes/kuka_kr20/link_ee.stl" scale="0.001 0.001 0.001"/>
      </geometry>
      <material name="">
        <color rgba="0.9647058823529412 0.47058823529411764 0.1568627450980392 1.0"/>
      </material>
    </visual>
    <collision>
      <origin rpy="0 0 0" xyz="-1.173 0 -1.45"/>
      <geometry>
        <mesh filename="package://acroba_resources/meshes/kuka_kr20/link_ee_convex.stl" scale="0.001 0.001 0.001"/>
      </geometry>
    </collision>
    <inertial>
      <mass value="1"/>
      <inertia ixx="0.08333333333333333" ixy="0.0" ixz="0.0" iyy="0.08333333333333333" iyz="0.0" izz="0.08333333333333333"/>
    </inertial>
  </link>
  <!--JOINTS-->
  <!-- the joint coordinate are the substaction between their coordinates (child-parent)*-1-->
  <joint name="joint_a1" type="revolute">
    <origin rpy="0 0 0" xyz="0 0 0.250"/>
    <parent link="base_link"/>
    <child link="link_1"/>
    <axis xyz="0 0 -1"/>
    <dynamics damping="0.7"/>
    <limit effort="0" lower="-3.2288591161895095" upper="3.2288591161895095" velocity="3.490658503988659"/>
  </joint>
  <joint name="joint_a2" type="revolute">
    <origin rpy="0 1.57 0 " xyz="0.16 -0.0889 0.27"/>
    <parent link="link_1"/>
    <child link="link_2"/>
    <axis xyz="0 1 0"/>
    <dynamics damping="0.7"/>
    <limit effort="0" lower="-3.2288591161895095" upper="1.1344640137963142" velocity="3.0543261909900767"/>
  </joint>
  <joint name="joint_a3" type="revolute">
    <origin rpy="0 -1.57 0" xyz="0 -0.009 0.78"/>
    <parent link="link_2"/>
    <child link="link_3"/>
    <axis xyz="0 1 0"/>
    <dynamics damping="0.7"/>
    <limit effort="0" lower="-2.4085543677521746" upper="3.0543261909900767" velocity="3.3161255787892263"/>
  </joint>
  <joint name="joint_fixed_1" type="fixed">
    <origin rpy="0 0 0" xyz="0.0 0.091 0"/>
    <parent link="link_3"/>
    <child link="link_3_1"/>
  </joint>
  <joint name="joint_a4" type="revolute">
    <origin rpy="0 0 0" xyz="0.3 0.0978 0.15"/>
    <parent link="link_3"/>
    <child link="link_4"/>
    <axis xyz="-1 0 0"/>
    <dynamics damping="0.7"/>
    <limit effort="0" lower="-6.1086523819801535" upper="6.1086523819801535" velocity="7.504915783575617"/>
  </joint>
  <joint name="joint_fixed_2" type="fixed">
    <origin rpy="0 0 0" xyz="0.41 0 0"/>
    <parent link="link_4"/>
    <child link="link_5"/>
  </joint>
  <joint name="joint_a5" type="revolute">
    <origin rpy="0 0 0" xyz="0.15 0 0"/>
    <parent link="link_5"/>
    <child link="link_6"/>
    <axis xyz="0 1 0"/>
    <dynamics damping="0.7"/>
    <limit effort="0" lower="-2.0943951023931953" upper="2.0943951023931953" velocity="7.504915783575617"/>
  </joint>
  <joint name="joint_a6" type="revolute">
    <origin rpy="0 0 0" xyz="0.153 0 0"/>
    <parent link="link_6"/>
    <child link="link_7"/>
    <axis xyz="-1 0 0"/>
    <dynamics damping="0.7"/>
    <limit effort="0" lower="-6.1086523819801535" upper="6.1086523819801535" velocity="10.995574287564276"/>
  </joint>
  <!-- ROS base_link to UR 'Base' Coordinates transform -->
  <link name="base"/>
  <joint name="base_link-base_fixed_joint" type="fixed">
    <origin rpy="0 0 0" xyz="0 0 0"/>
    <parent link="base_link"/>
    <child link="base"/>
  </joint>
  <!-- ROS-Industrial 'flange' frame: attachment point for EEF models -->
  <link name="flange"/>
  <joint name="joint_6-flange" type="fixed">
    <origin rpy="0 0 0" xyz="0 0 0"/>
    <parent link="link_7"/>
    <child link="flange"/>
  </joint>
  <!-- ROS-Industrial 'tool0' frame: all-zeros tool frame -->
  <link name="tool0"/>
  <joint name="link_6-tool0" type="fixed">
    <origin rpy="0 -1.5707963267948966 3.141592653589793" xyz="0 0 0.001"/>
    <parent link="link_7"/>
    <child link="tool0"/>
  </joint>
  <!--Gazebo robot control-->
  <!--<gazebo>
      <plugin name="gazebo_ros_control" filename="libgazebo_ros_control.so">
        <robotNamespace>/kr20r1810</robotNamespace>
       
      </plugin>
    </gazebo>-->
  <gazebo reference="base_link">
    <mu1>0.2</mu1>
    <mu2>0.2</mu2>
    <material>Gazebo/Black</material>
  </gazebo>
  <!-- Link1 -->
  <gazebo reference="link_1">
    <material>Gazebo/Orange</material>
  </gazebo>
  <gazebo reference="link_2">
    <material>Gazebo/Orange</material>
  </gazebo>
  <!-- Link2 -->
  <gazebo reference="link_3">
    <mu1>0.2</mu1>
    <mu2>0.2</mu2>
    <material>Gazebo/Orange</material>
  </gazebo>
  <!-- Link3 -->
  <gazebo reference="link_3_1">
    <mu1>0.2</mu1>
    <mu2>0.2</mu2>
    <material>Gazebo/Orange</material>
  </gazebo>
  <gazebo reference="link_4">
    <mu1>0.2</mu1>
    <mu2>0.2</mu2>
    <material>Gazebo/Orange</material>
  </gazebo>
  <gazebo reference="link_5">
    <mu1>0.2</mu1>
    <mu2>0.2</mu2>
    <material>Gazebo/Orange</material>
  </gazebo>
  <gazebo reference="link_6">
    <mu1>0.2</mu1>
    <mu2>0.2</mu2>
    <material>Gazebo/Orange</material>
  </gazebo>
  <transmission name="joint_a1_trans">
    <type>transmission_interface/SimpleTransmission</type>
    <joint name="joint_a1">
      <hardwareInterface>hardware_interface/PositionJointInterface</hardwareInterface>
    </joint>
    <actuator name="joint_a1_motor">
      <hardwareInterface>hardware_interface/PositionJointInterface</hardwareInterface>
      <mechanicalReduction>1</mechanicalReduction>
    </actuator>
  </transmission>
  <transmission name="joint_a2_trans">
    <type>transmission_interface/SimpleTransmission</type>
    <joint name="joint_a2">
      <hardwareInterface>hardware_interface/PositionJointInterface</hardwareInterface>
    </joint>
    <actuator name="joint_a2_motor">
      <hardwareInterface>hardware_interface/PositionJointInterface</hardwareInterface>
      <mechanicalReduction>1</mechanicalReduction>
    </actuator>
  </transmission>
  <transmission name="joint_a3_trans">
    <type>transmission_interface/SimpleTransmission</type>
    <joint name="joint_a3">
      <hardwareInterface>hardware_interface/PositionJointInterface</hardwareInterface>
    </joint>
    <actuator name="joint_a3_motor">
      <hardwareInterface>hardware_interface/PositionJointInterface</hardwareInterface>
      <mechanicalReduction>1</mechanicalReduction>
    </actuator>
  </transmission>
  <transmission name="joint_a4_trans">
    <type>transmission_interface/SimpleTransmission</type>
    <joint name="joint_a4">
      <hardwareInterface>hardware_interface/PositionJointInterface</hardwareInterface>
    </joint>
    <actuator name="joint_a4_motor">
      <hardwareInterface>hardware_interface/PositionJointInterface</hardwareInterface>
      <mechanicalReduction>1</mechanicalReduction>
    </actuator>
  </transmission>
  <transmission name="joint_a5_trans">
    <type>transmission_interface/SimpleTransmission</type>
    <joint name="joint_a5">
      <hardwareInterface>hardware_interface/PositionJointInterface</hardwareInterface>
    </joint>
    <actuator name="joint_a5_motor">
      <hardwareInterface>hardware_interface/PositionJointInterface</hardwareInterface>
      <mechanicalReduction>1</mechanicalReduction>
    </actuator>
  </transmission>
  <transmission name="joint_a6_trans">
    <type>transmission_interface/SimpleTransmission</type>
    <joint name="joint_a6">
      <hardwareInterface>hardware_interface/PositionJointInterface</hardwareInterface>
    </joint>
    <actuator name="joint_a6_motor">
      <hardwareInterface>hardware_interface/PositionJointInterface</hardwareInterface>
      <mechanicalReduction>1</mechanicalReduction>
    </actuator>
  </transmission>
  <!-- Zivid Base Link -->
  <link name="base_camera">
    <!-- Visuals -->
    <visual>
      <origin rpy="1.5707963267948966 0 1.5707963267948966" xyz="-0.0030 -0.0758 0.0445"/>
      <material name="blue">
        <color rgba="0.25 0.25 0.25 1"/>
      </material>
      <geometry>
        <mesh filename="package://acroba_resources/meshes/sensors/zivid_one_plus/visual/zivid_one_plus.stl" scale="0.001 0.001 0.001"/>
      </geometry>
    </visual>
    <!-- Collisions -->
    <collision>
      <origin rpy="1.5707963267948966 0 1.5707963267948966" xyz="-0.0030 -0.0758 0.0445"/>
      <geometry>
        <mesh filename="package://acroba_resources/meshes/sensors/zivid_one_plus/collision/zivid_one_plus.stl" scale="0.001 0.001 0.001"/>
      </geometry>
    </collision>
    <!-- Inertia-->
    <inertial>
      <origin rpy="0 0 0" xyz="-0.00936000000 -0.00003000000 -0.00273000000"/>
      <mass value="2"/>
      <inertia ixx="0.00000429247" ixy="0.00000000000" ixz="0.00000002565" iyy="0.00000008027" iyz="0.00000000000" izz="0.00000427339"/>
    </inertial>
  </link>
  <!-- Zivid Optical (Measurement) and Projector Frames -->
  <link name="optical_frame"/>
  <link name="projector_frame"/>
  <gazebo reference="gazebo_cam_link">
    <!-- Depth (rgb) -->
    <sensor name="_frame_sensor" type="depth">
      <always_on>true</always_on>
      <update_rate>5.0</update_rate>
      <camera>
        <image>
          <format>R8G8B8</format>
          <width>1534</width>
          <!--1944 in dataset,1534 in practise-->
          <height>1150</height>
          <!--1222 in dataset, 1150 in practise-->
        </image>
        <horizontal_fov>0.471</horizontal_fov>
        <!-- According to the specification 27ยบ-->
        <clip>
          <near>0.1</near>
          <far>1</far>
        </clip>
      </camera>
      <plugin filename="libgazebo_ros_openni_kinect.so" name="_frame_controller">
        <alwaysOn>true</alwaysOn>
        <updateRate>0.0</updateRate>
        <cameraName></cameraName>
        <imageTopicName>rgb/image_raw</imageTopicName>
        <cameraInfoTopicName>rgb/camera_info</cameraInfoTopicName>
        <depthImageTopicName>depth/image_raw</depthImageTopicName>
        <depthImageCameraInfoTopicName>depth/camera_info</depthImageCameraInfoTopicName>
        <pointCloudTopicName>depth/points</pointCloudTopicName>
        <frameName>_optical_frame</frameName>
        <pointCloudCutoff>0.05</pointCloudCutoff>
        <pointCloudCutoffMax>5</pointCloudCutoffMax>
        <rangeMax>4.0</rangeMax>
        <!-- Distortion parameters not supported in gazebo 1.9.* plugins -->
        <!--distortionK1>0.00000001</distortionK1>
          <distortionK2>0.00000001</distortionK2>
          <distortionK3>0.00000001</distortionK3>
          <distortionT1>0.00000001</distortionT1>
          <distortionT2>0.00000001</distortionT2-->
      </plugin>
    </sensor>
  </gazebo>
  <!-- Zivid Optical (Measurement) and Projector Joints -->
  <joint name="optical_joint" type="fixed">
    <origin rpy="-1.5707963267948966 0 -1.7191493132144147" xyz="0.065 0.062 0.0445"/>
    <parent link="base_camera"/>
    <child link="optical_frame"/>
  </joint>
  <joint name="projector_joint" type="fixed">
    <origin rpy="-1.5707963267948966 0 -1.5707963267948966" xyz="-0.0030 -0.0758 0.0445"/>
    <parent link="base_camera"/>
    <child link="projector_frame"/>
  </joint>
  <!--joint for the gazebo plugin-->
  <link name="gazebo_cam_link"/>
  <joint name="gazebo_joint" type="fixed">
    <origin rpy="1.5707963267948966 -1.5707963267948966 0" xyz="0.0 0.0 0.0"/>
    <parent link="optical_frame"/>
    <child link="gazebo_cam_link"/>
  </joint>
  <link name="world"/>
  <joint name="world_joint" type="fixed">
    <parent link="world"/>
    <child link="base_link"/>
    <origin rpy="0.000000 0.000000 0.000000" xyz="0.000000 0.000000 0.0"/>
  </joint>
  <joint name="tool_joint" type="fixed">
    <parent link="tool0"/>
    <child link="base_camera"/>
    <origin rpy="0.000000 0.000000 3.1415926" xyz="0.000000 0.000000 0.0"/>
  </joint>
</robot>
