<?xml version="1.0" ?>
<!-- =================================================================================== -->
<!-- |    This document was autogenerated by xacro from /home/VICOMTECH/mojer/catkin_ws/src/acroba_ros/acroba_resources/urdf/ikor_cell.xacro | -->
<!-- |    EDITING THIS FILE BY HAND IS NOT RECOMMENDED                                 | -->
<!-- =================================================================================== -->
<robot name="ikor_cell">
  <transmission name="shoulder_1_trans">
    <type>transmission_interface/SimpleTransmission</type>
    <joint name="shoulder_1_joint">
      <hardwareInterface>hardware_interface/PositionJointInterface</hardwareInterface>
    </joint>
    <actuator name="shoulder_1_motor">
      <mechanicalReduction>1</mechanicalReduction>
    </actuator>
  </transmission>
  <transmission name="shoulder_2_trans">
    <type>transmission_interface/SimpleTransmission</type>
    <joint name="shoulder_2_joint">
      <hardwareInterface>hardware_interface/PositionJointInterface</hardwareInterface>
    </joint>
    <actuator name="shoulder_2_motor">
      <mechanicalReduction>1</mechanicalReduction>
    </actuator>
  </transmission>
  <transmission name="elbow_1_trans">
    <type>transmission_interface/SimpleTransmission</type>
    <joint name="elbow_1_joint">
      <hardwareInterface>hardware_interface/PositionJointInterface</hardwareInterface>
    </joint>
    <actuator name="elbow_1_motor">
      <mechanicalReduction>1</mechanicalReduction>
    </actuator>
  </transmission>
  <transmission name="wrist_1_trans">
    <type>transmission_interface/SimpleTransmission</type>
    <joint name="wrist_1_joint">
      <hardwareInterface>hardware_interface/PositionJointInterface</hardwareInterface>
    </joint>
    <actuator name="wrist_1_motor">
      <mechanicalReduction>1</mechanicalReduction>
    </actuator>
  </transmission>
  <transmission name="wrist_2_trans">
    <type>transmission_interface/SimpleTransmission</type>
    <joint name="wrist_2_joint">
      <hardwareInterface>hardware_interface/PositionJointInterface</hardwareInterface>
    </joint>
    <actuator name="wrist_2_motor">
      <mechanicalReduction>1</mechanicalReduction>
    </actuator>
  </transmission>
  <transmission name="wrist_3_trans">
    <type>transmission_interface/SimpleTransmission</type>
    <joint name="wrist_3_joint">
      <hardwareInterface>hardware_interface/PositionJointInterface</hardwareInterface>
    </joint>
    <actuator name="wrist_3_motor">
      <mechanicalReduction>1</mechanicalReduction>
    </actuator>
  </transmission>
  <link name="base_link">
    <visual>
      <geometry>
        <mesh filename="package://acroba_resources/meshes/tm900/visual/Base.STL"/>
      </geometry>
      <material name="Grey">
        <color rgba="0.5 0.5 0.5 1.0"/>
      </material>
    </visual>
    <collision>
      <geometry>
        <mesh filename="package://acroba_resources/meshes/tm900/collision/base.STL"/>
      </geometry>
    </collision>
    <inertial>
      <mass value="1.0"/>
      <origin rpy="0 0 0" xyz="0.0 0.0 0.0"/>
      <inertia ixx="0.00110833289" ixy="0.0" ixz="0.0" iyy="0.00110833289" iyz="0.0" izz="0.0018"/>
    </inertial>
  </link>
  <link name="shoulder_1_link">
    <visual>
      <geometry>
        <mesh filename="package://acroba_resources/meshes/tm900/visual/Shoulder1.STL"/>
      </geometry>
      <material name="DarkOlive">
        <color rgba="0.3 0.3 0.25 1.0"/>
      </material>
    </visual>
    <collision>
      <geometry>
        <mesh filename="package://acroba_resources/meshes/tm900/collision/shoulder_1.STL"/>
      </geometry>
    </collision>
    <inertial>
      <mass value="4.5"/>
      <origin rpy="0 0 0" xyz="0.0 0.0 0.0"/>
      <inertia ixx="0.012487495005" ixy="0.0" ixz="0.0" iyy="0.012487495005" iyz="0.0" izz="0.0081"/>
    </inertial>
  </link>
  <joint name="shoulder_1_joint" type="revolute">
    <parent link="base_link"/>
    <child link="shoulder_1_link"/>
    <origin rpy="-1.570796325 0.0 0.0" xyz="0.0 0.0 0.1451"/>
    <axis xyz="0 -1 0"/>
    <limit effort="150.0" lower="-6.2831853" upper="6.2831853" velocity="3.15"/>
    <dynamics damping="0.0" friction="0.0"/>
  </joint>
  <link name="arm_1_link">
    <visual>
      <geometry>
        <mesh filename="package://acroba_resources/meshes/tm900/visual/Arm1.STL"/>
      </geometry>
      <material name="DarkOlive">
        <color rgba="0.3 0.3 0.25 1.0"/>
      </material>
    </visual>
    <collision>
      <geometry>
        <mesh filename="package://acroba_resources/meshes/tm900/collision/arm_1.STL"/>
      </geometry>
    </collision>
    <inertial>
      <mass value="11.0"/>
      <origin rpy="0 0 0" xyz="0.0 0.0 0.28"/>
      <inertia ixx="0.29736654772" ixy="0.0" ixz="0.0" iyy="0.29736654772" iyz="0.0" izz="0.019799999999999998"/>
    </inertial>
  </link>
  <joint name="shoulder_2_joint" type="revolute">
    <parent link="shoulder_1_link"/>
    <child link="arm_1_link"/>
    <origin rpy="0.0 0.0 -1.570796325" xyz="0.0 0.0 -0.146"/>
    <axis xyz="0 0 1"/>
    <limit effort="150.0" lower="-4.7123889750000005" upper="4.7123889750000005" velocity="3.15"/>
    <dynamics damping="0.0" friction="0.0"/>
  </joint>
  <link name="arm_2_link">
    <visual>
      <geometry>
        <mesh filename="package://acroba_resources/meshes/tm900/visual/Arm2.STL"/>
      </geometry>
      <material name="DarkOlive">
        <color rgba="0.3 0.3 0.25 1.0"/>
      </material>
    </visual>
    <collision>
      <geometry>
        <mesh filename="package://acroba_resources/meshes/tm900/collision/arm_2.STL"/>
      </geometry>
    </collision>
    <inertial>
      <mass value="2.5"/>
      <origin rpy="0 0 0" xyz="0.0 0.0 0.25"/>
      <inertia ixx="0.054333311599999996" ixy="0.0" ixz="0.0" iyy="0.054333311599999996" iyz="0.0" izz="0.0045"/>
    </inertial>
  </link>
  <joint name="elbow_1_joint" type="revolute">
    <parent link="arm_1_link"/>
    <child link="arm_2_link"/>
    <origin rpy="0.0 0.0 0.0" xyz="0.429 0.0 0.1298"/>
    <axis xyz="0 0 1"/>
    <limit effort="150.0" lower="-4.7123889750000005" upper="4.7123889750000005" velocity="3.15"/>
    <dynamics damping="0.0" friction="0.0"/>
  </joint>
  <link name="wrist_1_link">
    <visual>
      <geometry>
        <mesh filename="package://acroba_resources/meshes/tm900/visual/Wrist1.STL"/>
      </geometry>
      <material name="DarkOlive">
        <color rgba="0.3 0.3 0.25 1.0"/>
      </material>
    </visual>
    <collision>
      <geometry>
        <mesh filename="package://acroba_resources/meshes/tm900/collision/wrist_1.STL"/>
      </geometry>
    </collision>
    <inertial>
      <mass value="1.45"/>
      <origin rpy="0 0 0" xyz="0.0 0.0 0.0"/>
      <inertia ixx="0.13223994710399997" ixy="0.0" ixz="0.0" iyy="0.13223994710399997" iyz="0.0" izz="0.261"/>
    </inertial>
  </link>
  <joint name="wrist_1_joint" type="revolute">
    <parent link="arm_2_link"/>
    <child link="wrist_1_link"/>
    <origin rpy="1.570796325 0.0 1.570796325" xyz="0.4115 0.0 -0.10600000000000001"/>
    <axis xyz="0 1 0"/>
    <limit effort="28.0" lower="-6.2831853" upper="6.2831853" velocity="3.2"/>
    <dynamics damping="0.0" friction="0.0"/>
  </joint>
  <link name="wrist_2_link">
    <visual>
      <geometry>
        <mesh filename="package://acroba_resources/meshes/tm900/visual/Wrist2.STL"/>
      </geometry>
      <material name="DarkOlive">
        <color rgba="0.3 0.3 0.25 1.0"/>
      </material>
    </visual>
    <collision>
      <geometry>
        <mesh filename="package://acroba_resources/meshes/tm900/collision/wrist_2.STL"/>
      </geometry>
    </collision>
    <inertial>
      <mass value="1.45"/>
      <origin rpy="0 0 0" xyz="0.0 0.0 0.0"/>
      <inertia ixx="0.13223994710399997" ixy="0.0" ixz="0.0" iyy="0.13223994710399997" iyz="0.0" izz="0.261"/>
    </inertial>
  </link>
  <joint name="wrist_2_joint" type="revolute">
    <parent link="wrist_1_link"/>
    <child link="wrist_2_link"/>
    <origin rpy="1.570796325 0.0 0.0" xyz="0.0 0.0 0.106"/>
    <axis xyz="0 1 0"/>
    <limit effort="28.0" lower="-6.2831853" upper="6.2831853" velocity="3.2"/>
    <dynamics damping="0.0" friction="0.0"/>
  </joint>
  <link name="wrist_3_link">
    <visual>
      <geometry>
        <mesh filename="package://acroba_resources/meshes/tm900/visual/Wrist3.STL"/>
      </geometry>
      <origin rpy="0 0 0" xyz="0 0 0.015"/>
      <material name="Grey">
        <color rgba="0.5 0.5 0.5 1.0"/>
      </material>
    </visual>
    <collision>
      <geometry>
        <mesh filename="package://acroba_resources/meshes/tm900/collision/wrist_3.STL"/>
      </geometry>
    </collision>
    <inertial>
      <mass value="0.4"/>
      <origin rpy="0 0 0" xyz="0.0 0.0 0.0"/>
      <inertia ixx="0.036479985407999994" ixy="0.0" ixz="0.0" iyy="0.036479985407999994" iyz="0.0" izz="0.072"/>
    </inertial>
  </link>
  <joint name="wrist_3_joint" type="revolute">
    <parent link="wrist_2_link"/>
    <child link="wrist_3_link"/>
    <origin rpy="0.0 0.0 0.0" xyz="0.0 0.0 0.0565"/>
    <axis xyz="0 0 1"/>
    <limit effort="28.0" lower="-6.2831853" upper="6.2831853" velocity="3.2"/>
    <dynamics damping="0.0" friction="0.0"/>
  </joint>
  <link name="tool0"/>
  <!-- Frame coincident with all-zeros TCP on TM controller -->
  <joint name="wrist3_joint_tool0" type="fixed">
    <parent link="wrist_3_link"/>
    <child link="tool0"/>
    <origin rpy="0.0 0.0 0.0" xyz="0.0 0.0 0.0579"/>
  </joint>
  <link name="extension">
    <visual>
      <origin rpy="0 0 0" xyz="0.0 0.0 0.0"/>
      <geometry>
        <mesh filename="package://acroba_resources/meshes/miscellaneous/supportikor1/gripper_extension.stl"/>
      </geometry>
      <material name="Grey">
        <color rgba="0.5 0.5 0.5 1.0"/>
      </material>
    </visual>
    <collision>
      <origin rpy="0 0 0" xyz="0.0 0.0 0.046"/>
      <geometry>
        <cylinder length="0.092" radius="0.0315"/>
      </geometry>
    </collision>
    <inertial>
      <mass value="0.2"/>
      <origin rpy="0 0 0" xyz="0.0 0.0 0.0"/>
      <inertia ixx="0.000190679090395" ixy="0.0" ixz="0.0" iyy="0.000190679090395" iyz="0.0" izz="9.9225e-05"/>
    </inertial>
  </link>
  <link name="extension_top">
    <visual>
      <origin rpy="0 0 0" xyz="0.0 0.0 0.01"/>
      <geometry>
        <mesh filename="package://acroba_resources/meshes/miscellaneous/supportikor1/gripper_extension_top.stl"/>
      </geometry>
      <material name="Grey">
        <color rgba="0.5 0.5 0.5 1.0"/>
      </material>
    </visual>
    <collision>
      <origin rpy="0 0 0" xyz="0.0 0.0 0.005"/>
      <geometry>
        <cylinder length="0.01" radius="0.0315"/>
      </geometry>
    </collision>
    <inertial>
      <mass value="0.2"/>
      <origin rpy="0 0 0" xyz="0.0 0.0 0.0"/>
      <inertia ixx="0.000190679090395" ixy="0.0" ixz="0.0" iyy="0.000190679090395" iyz="0.0" izz="9.9225e-05"/>
    </inertial>
  </link>
  <joint name="joint_extensions" type="fixed">
    <parent link="extension"/>
    <child link="extension_top"/>
    <origin rpy="0.0 0.0 0.0" xyz="0.0 0.0 0.092"/>
  </joint>
  <link name="extension_tool0"/>
  <joint name="joint_extensiontool" type="fixed">
    <parent link="extension_top"/>
    <child link="extension_tool0"/>
    <origin rpy="0.0 0.0 0.0" xyz="0.0 0.0 0.01"/>
  </joint>
  <disable_collision link1="extension" link2="extension_top"/>
  <material name="pgc_dark_grey">
    <color rgba="0.3 0.3 0.3 1.0"/>
  </material>
  <material name="pgc_grey">
    <color rgba="0.45 0.45 0.45 1.0"/>
  </material>
  <!-- Finger and body intersect for 1.3mm this is taking into account in finger_length-->
  <link name="base_tool">
    <visual>
      <origin rpy="0 0 0" xyz="0.0 0.0 0.0"/>
      <geometry>
        <mesh filename="package://acroba_resources/meshes/pgc50/body.dae" scale="0.001 0.001 0.001"/>
      </geometry>
      <material name="pgc_grey"/>
    </visual>
    <collision>
      <origin rpy="0 0 0" xyz="0.0 0.0 0.0"/>
      <geometry>
        <mesh filename="package://acroba_resources/meshes/pgc50/body.stl" scale="0.001 0.001 0.001"/>
      </geometry>
    </collision>
    <inertial>
      <mass value="0.5"/>
      <inertia ixx="0.0037" ixy="0.0" ixz="0.0" iyy="0.0037" iyz="0.0" izz="0.0146"/>
    </inertial>
  </link>
  <link name="base_finger_1">
    <visual>
      <origin rpy="0 0 0" xyz="0.0 0.0 0.0"/>
      <geometry>
        <mesh filename="package://acroba_resources/meshes/pgc50/finger_holder_1.stl" scale="0.001 0.001 0.001"/>
      </geometry>
      <material name="pgc_dark_grey"/>
    </visual>
    <collision>
      <origin rpy="0 0 0" xyz="0.0 0.0 0.0"/>
      <geometry>
        <mesh filename="package://acroba_resources/meshes/pgc50/finger_holder_1.stl" scale="0.001 0.001 0.001"/>
      </geometry>
    </collision>
    <inertial>
      <mass value="0.05"/>
      <inertia ixx="0.0037" ixy="0.0" ixz="0.0" iyy="0.0037" iyz="0.0" izz="0.0146"/>
    </inertial>
  </link>
  <link name="base_finger_2">
    <visual>
      <origin rpy="0 0 0" xyz="0.0 0.0 0.0"/>
      <geometry>
        <mesh filename="package://acroba_resources/meshes/pgc50/finger_holder_2.stl" scale="0.001 0.001 0.001"/>
      </geometry>
      <material name="pgc_dark_grey"/>
    </visual>
    <collision>
      <origin rpy="0 0 0" xyz="0.0 0.0 0.0"/>
      <geometry>
        <mesh filename="package://acroba_resources/meshes/pgc50/finger_holder_2.stl" scale="0.001 0.001 0.001"/>
      </geometry>
    </collision>
    <inertial>
      <mass value="0.05"/>
      <inertia ixx="0.0037" ixy="0.0" ixz="0.0" iyy="0.0037" iyz="0.0" izz="0.0146"/>
    </inertial>
  </link>
  <link name="finger_1">
    <visual>
      <origin rpy="0.0 0.0 0.0" xyz="0 0 0"/>
      <geometry>
        <mesh filename="package://acroba_resources/meshes/pgc50/finger_1.stl" scale="0.001 0.001 0.001"/>
      </geometry>
      <material name="pgc_dark_grey"/>
    </visual>
    <collision>
      <origin rpy="0.0 0.0 0.0" xyz="0 0 0"/>
      <geometry>
        <mesh filename="package://acroba_resources/meshes/pgc50/finger_1.stl" scale="0.001 0.001 0.001"/>
      </geometry>
    </collision>
    <inertial>
      <mass value="0.1"/>
      <inertia ixx="0.0037" ixy="0.0" ixz="0.0" iyy="0.0037" iyz="0.0" izz="0.0146"/>
    </inertial>
  </link>
  <link name="finger_2">
    <visual>
      <origin rpy="0.0 0.0 0.0" xyz="0 0 0"/>
      <geometry>
        <mesh filename="package://acroba_resources/meshes/pgc50/finger_2.stl" scale="0.001 0.001 0.001"/>
      </geometry>
      <material name="pgc_dark_grey"/>
    </visual>
    <collision>
      <origin rpy="0.0 0.0 0.0" xyz="0 0 0"/>
      <geometry>
        <mesh filename="package://acroba_resources/meshes/pgc50/finger_2.stl" scale="0.001 0.001 0.001"/>
      </geometry>
    </collision>
    <inertial>
      <mass value="0.1"/>
      <inertia ixx="0.0037" ixy="0.0" ixz="0.0" iyy="0.0037" iyz="0.0" izz="0.0146"/>
    </inertial>
  </link>
  <joint name="joint_base_finger_1" type="prismatic">
    <origin rpy="0 0 0" xyz="0 0 0"/>
    <parent link="base_tool"/>
    <child link="base_finger_1"/>
    <axis xyz="1 0 0"/>
    <limit effort="50" lower="0" upper="0.0175" velocity="10"/>
  </joint>
  <joint name="joint_base_finger_2" type="prismatic">
    <origin rpy="0 0 0" xyz="0 0 0"/>
    <parent link="base_tool"/>
    <child link="base_finger_2"/>
    <axis xyz="-1 0 0"/>
    <limit effort="50" lower="0" upper="0.0175" velocity="10"/>
  </joint>
  <joint name="joint_finger_1" type="fixed">
    <origin rpy="0 0 0" xyz="0 0 0"/>
    <parent link="base_finger_1"/>
    <child link="finger_1"/>
  </joint>
  <joint name="joint_finger_2" type="fixed">
    <origin rpy="0 0 0" xyz="0 0 0"/>
    <parent link="base_finger_2"/>
    <child link="finger_2"/>
  </joint>
  <link name="gripping_point"/>
  <joint name="joint_gripping" type="fixed">
    <origin rpy="0 0 0" xyz="0. 0 0.1242"/>
    <parent link="base_tool"/>
    <child link="gripping_point"/>
  </joint>
  <!-- Add gazebo colors-->
  <gazebo reference="base_tool">
    <material>Gazebo/FlatBlack</material>
  </gazebo>
  <gazebo reference="base_finger_1">
    <material>Gazebo/FlatBlack</material>
  </gazebo>
  <gazebo reference="base_finger_2">
    <material>Gazebo/FlatBlack</material>
  </gazebo>
  <gazebo reference="finger_1">
    <material>Gazebo/FlatBlack</material>
  </gazebo>
  <gazebo reference="finger_2">
    <material>Gazebo/FlatBlack</material>
  </gazebo>
  <!-- Transmissions-->
  <transmission name="joint_finger1_trans">
    <type>transmission_interface/SimpleTransmission</type>
    <joint name="joint_base_finger_1">
      <hardwareInterface>hardware_interface/EffortJointInterface</hardwareInterface>
    </joint>
    <actuator name="joint_base_finger_1_motor">
      <hardwareInterface>hardware_interface/EffortJointInterface</hardwareInterface>
      <mechanicalReduction>1</mechanicalReduction>
    </actuator>
  </transmission>
  <transmission name="joint_finger2_trans">
    <type>transmission_interface/SimpleTransmission</type>
    <joint name="joint_base_finger_2">
      <hardwareInterface>hardware_interface/EffortJointInterface</hardwareInterface>
    </joint>
    <actuator name="joint_base_finger_2_motor">
      <hardwareInterface>hardware_interface/EffortJointInterface</hardwareInterface>
      <mechanicalReduction>1</mechanicalReduction>
    </actuator>
  </transmission>
  <disable_collision link1="wrist_3_link" link2="base_tool">
  </disable_collision>
  <!-- Disabling collision for gripper-->
  <disable_collision link1="base_tool" link2="base_finger_1">
  </disable_collision>
  <disable_collision link1="base_tool" link2="base_finger_2">
  </disable_collision>
  <disable_collision link1="base_finger_2" link2="base_finger_1">
  </disable_collision>
  <disable_collision link1="base_tool" link2="finger_1">
  </disable_collision>
  <disable_collision link1="base_tool" link2="finger_2">
  </disable_collision>
  <link name="world"/>
  <joint name="tool_extension_joint" type="fixed">
    <parent link="tool0"/>
    <child link="extension"/>
    <origin rpy="0.0 0.0 0.0" xyz="0.0 0.0 0.0"/>
  </joint>
  <joint name="tool__extension_joint" type="fixed">
    <parent link="extension_tool0"/>
    <child link="base_tool"/>
    <origin rpy="0.0 0.0 0.0" xyz="0.0 0.0 0.0"/>
  </joint>
  <!-- Disabling collision between tool and robot, maybe not necessary-->
  <disable_collision link1="wrist_3_link" link2="extension"/>
  <disable_collision link1="extension_tool0" link2="base_tool"/>
  <joint name="world_joint" type="fixed">
    <parent link="world"/>
    <child link="base_link"/>
    <origin rpy="0 0 0" xyz="0.451 -0.833 0.895"/>
  </joint>
  <link name="cell_floor">
    <visual>
      <origin rpy="0 0 0" xyz="0 0 -0.0025"/>
      <geometry>
        <box size="4 4 0.005"/>
      </geometry>
      <material name="floor">
        <color rgba="0.78 0.78 0.78 1"/>
      </material>
    </visual>
    <collision>
      <origin rpy="0 0 0" xyz="0 0 -0.0025"/>
      <geometry>
        <box size="4 4 0.005"/>
      </geometry>
    </collision>
  </link>
  <joint name="floor_joint" type="fixed">
    <parent link="world"/>
    <child link="cell_floor"/>
    <origin rpy="0 0 0" xyz="0 0 0"/>
  </joint>
  <link name="vibrating_frame"/>
  <joint name="vibrating_joint" type="fixed">
    <parent link="world"/>
    <child link="vibrating_frame"/>
    <origin rpy="0 0 -1.5707963267948966" xyz="-0.014 -0.582  0.798"/>
  </joint>
  <link name="vibrating_cube">
    <visual>
      <origin rpy="0 0 0" xyz="0 0 0.0"/>
      <geometry>
        <mesh filename="package://acroba_resources/meshes/ikor_case/ASYCUBE.dae" scale="1 1 1"/>
      </geometry>
      <material name="cube">
        <color rgba="0.5 0.5 0.5 1"/>
      </material>
    </visual>
    <collision>
      <origin rpy="0 0 0" xyz="0 0 0.0"/>
      <geometry>
        <mesh filename="package://acroba_resources/meshes/ikor_case/ASYCUBE.dae" scale="1 1 1"/>
      </geometry>
    </collision>
  </link>
  <joint name="cube_joint" type="fixed">
    <parent link="vibrating_frame"/>
    <child link="vibrating_cube"/>
    <origin rpy="1.5707963267948966  0 -1.5707963267948966" xyz="-0.1969 -0.0144 0.1059"/>
  </joint>
  <link name="vibrating_table">
    <visual>
      <origin rpy="0 0 0" xyz="0 0 0.0"/>
      <geometry>
        <mesh filename="package://acroba_resources/meshes/ikor_case/ASY_HOPPER.dae" scale="1 1 1"/>
      </geometry>
      <material name="cube">
        <color rgba="0.5 0.5 0.5 1"/>
      </material>
    </visual>
    <collision>
      <origin rpy="0 0 0" xyz="0 0 0.0"/>
      <geometry>
        <mesh filename="package://acroba_resources/meshes/ikor_case/ASY_HOPPER.dae" scale="1 1 1"/>
      </geometry>
    </collision>
  </link>
  <joint name="table_joint" type="fixed">
    <parent link="vibrating_frame"/>
    <child link="vibrating_table"/>
    <origin rpy="1.5707963267948966 0 0" xyz="-0.31192 0.16958 0.0759"/>
  </joint>
  <link name="operator_table">
    <visual>
      <origin rpy="0 0 0" xyz="0 0 0.0"/>
      <geometry>
        <mesh filename="package://acroba_resources/meshes/ikor_case/Puesto_de_montaje.dae" scale="1 1 1"/>
      </geometry>
      <material name="cube">
        <color rgba="0.5 0.5 0.5 1"/>
      </material>
    </visual>
    <!--<collision>
      <origin xyz="0 0 0.0" rpy="0 0 0"/>
      <geometry>
         <mesh filename="package://acroba_resources/meshes/ikor_case/Puesto_de_montaje.dae" scale="1 1 1"/>
      </geometry>
    </collision>-->
    <collision>
      <origin rpy="0 0 0" xyz="1 -0.07 0.899"/>
      <geometry>
        <box size="2 0.44 0.005"/>
      </geometry>
    </collision>
    <collision>
      <origin rpy="0 0 0" xyz="1 0.8256 0.9225"/>
      <geometry>
        <box size="1.9 0.48 0.005"/>
      </geometry>
    </collision>
    <collision>
      <origin rpy="0 0 0" xyz="1 0.62 1.1125"/>
      <geometry>
        <box size="2.002 0.238 0.005"/>
      </geometry>
    </collision>
    <collision>
      <origin rpy="0 0 0" xyz="1 0.64 1.5"/>
      <geometry>
        <box size="2 0.005 3"/>
      </geometry>
    </collision>
  </link>
  <joint name="operatorjoint" type="fixed">
    <parent link="world"/>
    <child link="operator_table"/>
    <origin rpy="0 0 1.5707" xyz="-0.017 -1.412 0"/>
  </joint>
  <link name="intermediate_surface">
    <visual>
      <origin rpy="0 0 0" xyz="0 0 0"/>
      <geometry>
        <box size="0.123 0.1 0.005"/>
      </geometry>
      <material name="inter_suface">
        <color rgba="1 0.76 0.82 1"/>
      </material>
    </visual>
    <collision>
      <origin rpy="0 0 0" xyz="0 0 0"/>
      <geometry>
        <box size="0.123 0.1 0.005"/>
      </geometry>
    </collision>
  </link>
  <link name="inter_joint"/>
  <joint name="inter_joint1" type="fixed">
    <parent link="world"/>
    <child link="inter_joint"/>
    <origin rpy="0 -0.262 0" xyz="0.087 -0.74 0.9202"/>
  </joint>
  <joint name="inter_joint2" type="fixed">
    <parent link="inter_joint"/>
    <child link="intermediate_surface"/>
    <origin rpy="0 0 0" xyz="0 0 0"/>
  </joint>
  <!--  Camera -->
  <link name="photoneo">
    <visual>
      <origin rpy="0 0 0" xyz="0 0 0.0"/>
      <geometry>
        <mesh filename="package://acroba_resources/meshes/ikor_case/photoneo.dae" scale="1 1 1"/>
      </geometry>
      <material name="photoneo_color">
        <color rgba="0.1 0.2 0.90 1"/>
      </material>
    </visual>
    <collision>
      <origin rpy="0 0 0" xyz="0 0 0.0"/>
      <geometry>
        <mesh filename="package://acroba_resources/meshes/ikor_case/photoneo.dae" scale="1 1 1"/>
      </geometry>
    </collision>
  </link>
  <link name="camera_frame_intermediate"/>
  <joint name="camera_joint" type="fixed">
    <parent link="world"/>
    <child link="camera_frame_intermediate"/>
    <origin rpy="1.5707963267948966 0 3.141592653589793" xyz="0.1054 -0.4667 1.2103"/>
  </joint>
  <joint name="camera_joint2" type="fixed">
    <parent link="camera_frame_intermediate"/>
    <child link="photoneo"/>
    <origin rpy="0 0 0" xyz="0.026 0.0289 0.0045"/>
  </joint>
</robot>
