<?xml version="1.0" ?>
<!-- =================================================================================== -->
<!-- |    This document was autogenerated by xacro from ./IMR_zivid_cell_inspection.xacro | -->
<!-- |    EDITING THIS FILE BY HAND IS NOT RECOMMENDED                                 | -->
<!-- =================================================================================== -->
<robot name="imr_cell">
  <!-- measured from model -->
  <!--property name="shoulder_height" value="0.089159" /-->
  <!--property name="shoulder_offset" value="0.13585" /-->
  <!-- shoulder_offset - elbow_offset + wrist_1_length = 0.10915 -->
  <!--property name="upper_arm_length" value="0.42500" /-->
  <!--property name="elbow_offset" value="0.1197" /-->
  <!-- CAD measured -->
  <!--property name="forearm_length" value="0.39225" /-->
  <!--property name="wrist_1_length" value="0.093" /-->
  <!-- CAD measured -->
  <!--property name="wrist_2_length" value="0.09465" /-->
  <!-- In CAD this distance is 0.930, but in the spec it is 0.09465 -->
  <!--property name="wrist_3_length" value="0.0823" /-->
  <!-- manually measured -->
  <link name="base_link">
    <visual>
      <geometry>
        <mesh filename="package://acroba_resources/meshes/ur5/visual/base.dae"/>
      </geometry>
      <material name="LightGrey">
        <color rgba="0.7 0.7 0.7 1.0"/>
      </material>
    </visual>
    <collision>
      <geometry>
        <mesh filename="package://acroba_resources/meshes/ur5/collision/base.stl"/>
      </geometry>
    </collision>
    <inertial>
      <mass value="4.0"/>
      <origin rpy="0 0 0" xyz="0.0 0.0 0.0"/>
      <inertia ixx="0.00443333156" ixy="0.0" ixz="0.0" iyy="0.00443333156" iyz="0.0" izz="0.0072"/>
    </inertial>
  </link>
  <joint name="shoulder_pan_joint" type="revolute">
    <parent link="base_link"/>
    <child link="shoulder_link"/>
    <origin rpy="0.0 0.0 0.0" xyz="0.0 0.0 0.089159"/>
    <axis xyz="0 0 1"/>
    <limit effort="150.0" lower="-6.283185307179586" upper="6.283185307179586" velocity="3.15"/>
    <dynamics damping="0.0" friction="0.0"/>
  </joint>
  <link name="shoulder_link">
    <visual>
      <geometry>
        <mesh filename="package://acroba_resources/meshes/ur5/visual/shoulder.dae"/>
      </geometry>
      <material name="LightGrey">
        <color rgba="0.7 0.7 0.7 1.0"/>
      </material>
    </visual>
    <collision>
      <geometry>
        <mesh filename="package://acroba_resources/meshes/ur5/collision/shoulder.stl"/>
      </geometry>
    </collision>
    <inertial>
      <mass value="3.7"/>
      <origin rpy="0 0 0" xyz="0.0 0.0 0.0"/>
      <inertia ixx="0.010267495893" ixy="0.0" ixz="0.0" iyy="0.010267495893" iyz="0.0" izz="0.00666"/>
    </inertial>
  </link>
  <joint name="shoulder_lift_joint" type="revolute">
    <parent link="shoulder_link"/>
    <child link="upper_arm_link"/>
    <origin rpy="0.0 1.5707963267948966 0.0" xyz="0.0 0.13585 0.0"/>
    <axis xyz="0 1 0"/>
    <limit effort="150.0" lower="-6.283185307179586" upper="6.283185307179586" velocity="3.15"/>
    <dynamics damping="0.0" friction="0.0"/>
  </joint>
  <link name="upper_arm_link">
    <visual>
      <geometry>
        <mesh filename="package://acroba_resources/meshes/ur5/visual/upperarm.dae"/>
      </geometry>
      <material name="LightGrey">
        <color rgba="0.7 0.7 0.7 1.0"/>
      </material>
    </visual>
    <collision>
      <geometry>
        <mesh filename="package://acroba_resources/meshes/ur5/collision/upperarm.stl"/>
      </geometry>
    </collision>
    <inertial>
      <mass value="8.393"/>
      <origin rpy="0 0 0" xyz="0.0 0.0 0.28"/>
      <inertia ixx="0.22689067591036005" ixy="0.0" ixz="0.0" iyy="0.22689067591036005" iyz="0.0" izz="0.0151074"/>
    </inertial>
  </link>
  <joint name="elbow_joint" type="revolute">
    <parent link="upper_arm_link"/>
    <child link="forearm_link"/>
    <origin rpy="0.0 0.0 0.0" xyz="0.0 -0.1197 0.425"/>
    <axis xyz="0 1 0"/>
    <limit effort="150.0" lower="-3.141592653589793" upper="3.141592653589793" velocity="3.15"/>
    <dynamics damping="0.0" friction="0.0"/>
  </joint>
  <link name="forearm_link">
    <visual>
      <geometry>
        <mesh filename="package://acroba_resources/meshes/ur5/visual/forearm.dae"/>
      </geometry>
      <material name="LightGrey">
        <color rgba="0.7 0.7 0.7 1.0"/>
      </material>
    </visual>
    <collision>
      <geometry>
        <mesh filename="package://acroba_resources/meshes/ur5/collision/forearm.stl"/>
      </geometry>
    </collision>
    <inertial>
      <mass value="2.275"/>
      <origin rpy="0 0 0" xyz="0.0 0.0 0.196125"/>
      <inertia ixx="0.03121679102890359" ixy="0.0" ixz="0.0" iyy="0.03121679102890359" iyz="0.0" izz="0.004095"/>
    </inertial>
  </link>
  <joint name="wrist_1_joint" type="revolute">
    <parent link="forearm_link"/>
    <child link="wrist_1_link"/>
    <origin rpy="0.0 1.5707963267948966 0.0" xyz="0.0 0.0 0.39225"/>
    <axis xyz="0 1 0"/>
    <limit effort="28.0" lower="-6.283185307179586" upper="6.283185307179586" velocity="3.2"/>
    <dynamics damping="0.0" friction="0.0"/>
  </joint>
  <link name="wrist_1_link">
    <visual>
      <geometry>
        <mesh filename="package://acroba_resources/meshes/ur5/visual/wrist1.dae"/>
      </geometry>
      <material name="LightGrey">
        <color rgba="0.7 0.7 0.7 1.0"/>
      </material>
    </visual>
    <collision>
      <geometry>
        <mesh filename="package://acroba_resources/meshes/ur5/collision/wrist1.stl"/>
      </geometry>
    </collision>
    <inertial>
      <mass value="1.219"/>
      <origin rpy="0 0 0" xyz="0.0 0.093 0.0"/>
      <inertia ixx="0.0025598989760400002" ixy="0.0" ixz="0.0" iyy="0.0025598989760400002" iyz="0.0" izz="0.0021942"/>
    </inertial>
  </link>
  <joint name="wrist_2_joint" type="revolute">
    <parent link="wrist_1_link"/>
    <child link="wrist_2_link"/>
    <origin rpy="0.0 0.0 0.0" xyz="0.0 0.093 0.0"/>
    <axis xyz="0 0 1"/>
    <limit effort="28.0" lower="-6.283185307179586" upper="6.283185307179586" velocity="3.2"/>
    <dynamics damping="0.0" friction="0.0"/>
  </joint>
  <link name="wrist_2_link">
    <visual>
      <geometry>
        <mesh filename="package://acroba_resources/meshes/ur5/visual/wrist2.dae"/>
      </geometry>
      <material name="LightGrey">
        <color rgba="0.7 0.7 0.7 1.0"/>
      </material>
    </visual>
    <collision>
      <geometry>
        <mesh filename="package://acroba_resources/meshes/ur5/collision/wrist2.stl"/>
      </geometry>
    </collision>
    <inertial>
      <mass value="1.219"/>
      <origin rpy="0 0 0" xyz="0.0 0.0 0.09465"/>
      <inertia ixx="0.0025598989760400002" ixy="0.0" ixz="0.0" iyy="0.0025598989760400002" iyz="0.0" izz="0.0021942"/>
    </inertial>
  </link>
  <joint name="wrist_3_joint" type="revolute">
    <parent link="wrist_2_link"/>
    <child link="wrist_3_link"/>
    <origin rpy="0.0 0.0 0.0" xyz="0.0 0.0 0.09465"/>
    <axis xyz="0 1 0"/>
    <limit effort="28.0" lower="-6.283185307179586" upper="6.283185307179586" velocity="3.2"/>
    <dynamics damping="0.0" friction="0.0"/>
  </joint>
  <link name="wrist_3_link">
    <visual>
      <geometry>
        <mesh filename="package://acroba_resources/meshes/ur5/visual/wrist3.dae"/>
      </geometry>
      <material name="LightGrey">
        <color rgba="0.7 0.7 0.7 1.0"/>
      </material>
    </visual>
    <collision>
      <geometry>
        <mesh filename="package://acroba_resources/meshes/ur5/collision/wrist3.stl"/>
      </geometry>
    </collision>
    <inertial>
      <mass value="0.1879"/>
      <origin rpy="1.5707963267948966 0 0" xyz="0.0 0.06505 0.0"/>
      <inertia ixx="8.469589112163e-05" ixy="0.0" ixz="0.0" iyy="8.469589112163e-05" iyz="0.0" izz="0.0001321171875"/>
    </inertial>
  </link>
  <joint name="ee_fixed_joint" type="fixed">
    <parent link="wrist_3_link"/>
    <child link="ee_link"/>
    <origin rpy="0.0 0.0 1.5707963267948966" xyz="0.0 0.0823 0.0"/>
  </joint>
  <link name="ee_link">
    <collision>
      <geometry>
        <box size="0.01 0.01 0.01"/>
      </geometry>
      <origin rpy="0 0 0" xyz="-0.01 0 0"/>
    </collision>
  </link>
  <!-- ROS base_link to UR 'Base' Coordinates transform -->
  <link name="base"/>
  <joint name="base_link-base_fixed_joint" type="fixed">
    <!-- NOTE: this rotation is only needed as long as base_link itself is
                 not corrected wrt the real robot (ie: rotated over 180
                 degrees)
      -->
    <origin rpy="0 0 -3.141592653589793" xyz="0 0 0"/>
    <parent link="base_link"/>
    <child link="base"/>
  </joint>
  <!-- Frame coincident with all-zeros TCP on UR controller -->
  <link name="tool0"/>
  <joint name="wrist_3_link-tool0_fixed_joint" type="fixed">
    <origin rpy="-1.5707963267948966 0 0" xyz="0 0.0823 0"/>
    <parent link="wrist_3_link"/>
    <child link="tool0"/>
  </joint>
  <link name="base_tool">
    </link>
  <joint name="base_tool_joint" type="fixed">
    <parent link="base_tool"/>
    <child link="hand_link"/>
    <origin rpy="1.570796327 -1.570796327 0" xyz="0.000 0.000 0.000"/>
  </joint>
  <link name="hand_link">
    <collision>
      <origin rpy="0.00 0.00 0.00" xyz="0.00 0.00 0.00"/>
      <geometry>
        <mesh filename="package://acroba_resources/meshes/rg2/collision/RG2_Hand_col.STL"/>
      </geometry>
    </collision>
    <visual>
      <origin rpy="0.00 0.00 0.00" xyz="0.00 0.00 0.00"/>
      <geometry>
        <mesh filename="package://acroba_resources/meshes/rg2/visual/RG2_Hand_vis.STL"/>
      </geometry>
    </visual>
    <!-- <inertial>
            <origin xyz="0.058091 0.000192 -0.000016" rpy="0.00 0.00 0.00"/>
            <mass value="0.524520"/>
            <inertia ixx="0.000193" ixy="0.000000" ixz="0.000000"
                     iyy="0.000564" iyz="-0.000001"
                     izz="0.000636" />
        </inertial> -->
    <inertial>
      <origin rpy="0.00 0.00 0.00" xyz="0.061902 0.000129 -0.000005"/>
      <mass value="1.684558"/>
      <inertia ixx="0.000862" ixy="0.000000" ixz="0.000000" iyy="0.002401" iyz="-0.000001" izz="0.002620"/>
    </inertial>
  </link>
  <!-- Jari Kiri -->
  <joint name="gripper_joint" type="revolute">
    <parent link="hand_link"/>
    <child link="l_moment_arm_link"/>
    <origin rpy="0 0 0" xyz="0.105 0.017 0.010"/>
    <axis xyz="0 0 1"/>
    <limit effort="10.6" lower="-0.45" upper="1.570796327" velocity="3.14"/>
    <!-- <limit velocity="3.14" effort="100" lower="-3" upper="3" /> -->
    <dynamics damping="0.1" friction="0.0"/>
    <implicitSpringDamper>True</implicitSpringDamper>
  </joint>
  <link name="l_moment_arm_link">
    <collision>
      <origin rpy="0.00 0.00 0.00" xyz="0.00 0.00 0.00"/>
      <geometry>
        <mesh filename="package://acroba_resources/meshes/rg2/collision/RG2_LeftMomentArm_col.STL"/>
      </geometry>
    </collision>
    <visual>
      <origin rpy="0.00 0.00 0.00" xyz="0.00 0.00 0.00"/>
      <geometry>
        <mesh filename="package://acroba_resources/meshes/rg2/visual/RG2_LeftMomentArm_vis.STL"/>
      </geometry>
    </visual>
    <inertial>
      <origin rpy="0.00 0.00 0.00" xyz="0.017004 0.006397 -0.010300"/>
      <mass value="0.160209"/>
      <inertia ixx="0.000023" ixy="0.000019" ixz="0.000000" iyy="0.000072" iyz="0.000000" izz="0.000083"/>
    </inertial>
  </link>
  <joint name="l_finger_2_joint" type="revolute">
    <parent link="l_moment_arm_link"/>
    <child link="l_finger_link"/>
    <origin rpy="0 0 0" xyz="0.049 0.026 0.000"/>
    <axis xyz="0 0 1"/>
    <limit effort="10.6" lower="-1.570796327" upper="1.570796327" velocity="3.14"/>
    <!-- <limit velocity="3.14" effort="100" lower="-3" upper="3" /> -->
    <mimic joint="gripper_joint" multiplier="-1"/>
    <dynamics damping="0.1" friction="0.0"/>
    <implicitSpringDamper>True</implicitSpringDamper>
  </joint>
  <link name="l_finger_link">
    <collision>
      <origin rpy="0.00 0.00 0.00" xyz="0.00 0.00 0.00"/>
      <geometry>
        <mesh filename="package://acroba_resources/meshes/rg2/collision/RG2_LeftFinger_col.STL"/>
      </geometry>
    </collision>
    <visual>
      <origin rpy="0.00 0.00 0.00" xyz="0.00 0.00 0.00"/>
      <geometry>
        <mesh filename="package://acroba_resources/meshes/rg2/visual/RG2_LeftFinger_vis.STL"/>
      </geometry>
    </visual>
    <inertial>
      <origin rpy="0.00 0.00 0.00" xyz="0.024695 -0.010178 -0.010001"/>
      <mass value="0.081638"/>
      <inertia ixx="0.000006" ixy="-0.000005" ixz="0.000000" iyy="0.000025" iyz="0.000000" izz="0.000026"/>
    </inertial>
  </link>
  <joint name="l_finger_passive_joint" type="revolute">
    <parent link="hand_link"/>
    <child link="l_truss_arm_link"/>
    <origin rpy="0 0 0" xyz="0.122 0.008 0.010"/>
    <axis xyz="0 0 1"/>
    <limit effort="10.6" lower="-1.570796327" upper="1.570796327" velocity="3.14"/>
    <!-- <limit velocity="3.14" effort="100" lower="-3" upper="3" /> -->
    <mimic joint="gripper_joint" multiplier="1"/>
    <dynamics damping="0.1" friction="0.0"/>
    <implicitSpringDamper>True</implicitSpringDamper>
  </joint>
  <!-- <xacro:insert_transmission name="l_finger_passive_joint" /> -->
  <link name="l_truss_arm_link">
    <collision>
      <origin rpy="0.00 0.00 0.00" xyz="0.00 0.00 0.00"/>
      <geometry>
        <mesh filename="package://acroba_resources/meshes/rg2/collision/RG2_LeftTrussArm_col.STL"/>
      </geometry>
    </collision>
    <visual>
      <origin rpy="0.00 0.00 0.00" xyz="0.00 0.00 0.00"/>
      <geometry>
        <mesh filename="package://acroba_resources/meshes/rg2/visual/RG2_LeftTrussArm_vis.STL"/>
      </geometry>
    </visual>
    <inertial>
      <origin rpy="0.00 0.00 0.00" xyz="0.023075 0.012136 -0.010000"/>
      <mass value="0.065927"/>
      <inertia ixx="0.000010" ixy="0.000010" ixz="0.000000" iyy="0.000024" iyz="0.000000" izz="0.000025"/>
    </inertial>
  </link>
  <!-- Jari Kanan -->
  <joint name="r_finger_1_joint" type="revolute">
    <parent link="hand_link"/>
    <child link="r_moment_arm_link"/>
    <origin rpy="0 0 0" xyz="0.105 -0.017 0.010"/>
    <axis xyz="0 0 1"/>
    <limit effort="10.6" lower="-1.570796327" upper="1.570796327" velocity="3.14"/>
    <!-- <limit velocity="3.14" effort="100" lower="-3" upper="3" /> -->
    <mimic joint="gripper_joint" multiplier="-1"/>
    <dynamics damping="0.1" friction="0.0"/>
    <implicitSpringDamper>True</implicitSpringDamper>
  </joint>
  <link name="r_moment_arm_link">
    <collision>
      <origin rpy="0.00 0.00 0.00" xyz="0.00 0.00 0.00"/>
      <geometry>
        <mesh filename="package://acroba_resources/meshes/rg2/collision/RG2_RightMomentArm_col.STL"/>
      </geometry>
    </collision>
    <visual>
      <origin rpy="0.00 0.00 0.00" xyz="0.00 0.00 0.00"/>
      <geometry>
        <mesh filename="package://acroba_resources/meshes/rg2/visual/RG2_RightMomentArm_vis.STL"/>
      </geometry>
    </visual>
    <inertial>
      <origin rpy="0.00 0.00 0.00" xyz="0.017004 -0.006397 -0.010300"/>
      <mass value="0.160209"/>
      <inertia ixx="0.000023" ixy="-0.000019" ixz="0.000000" iyy="0.000072" iyz="0.000000" izz="0.000083"/>
    </inertial>
  </link>
  <joint name="r_finger_2_joint" type="revolute">
    <parent link="r_moment_arm_link"/>
    <child link="r_finger_link"/>
    <origin rpy="0 0 0" xyz="0.049 -0.026 0.000"/>
    <axis xyz="0 0 1"/>
    <limit effort="10.6" lower="-1.570796327" upper="1.570796327" velocity="3.14"/>
    <!-- <limit velocity="3.14" effort="100" lower="-3" upper="3" /> -->
    <mimic joint="gripper_joint" multiplier="1"/>
    <dynamics damping="0.1" friction="0.0"/>
    <implicitSpringDamper>True</implicitSpringDamper>
  </joint>
  <!-- <xacro:insert_transmission name="r_finger_2_joint" /> -->
  <link name="r_finger_link">
    <collision>
      <origin rpy="0.00 0.00 0.00" xyz="0.00 0.00 0.00"/>
      <geometry>
        <mesh filename="package://acroba_resources/meshes/rg2/collision/RG2_RightFinger_col.STL"/>
      </geometry>
    </collision>
    <visual>
      <origin rpy="0.00 0.00 0.00" xyz="0.00 0.00 0.00"/>
      <geometry>
        <mesh filename="package://acroba_resources/meshes/rg2/visual/RG2_RightFinger_vis.STL"/>
      </geometry>
    </visual>
    <inertial>
      <origin rpy="0.00 0.00 0.00" xyz="0.024695 0.010178 -0.010000"/>
      <mass value="0.081637"/>
      <inertia ixx="0.000006" ixy="0.000005" ixz="0.000000" iyy="0.000025" iyz="0.000000" izz="0.000026"/>
    </inertial>
  </link>
  <joint name="r_finger_passive_joint" type="revolute">
    <parent link="hand_link"/>
    <child link="r_truss_arm_link"/>
    <origin rpy="0 0 0" xyz="0.122 -0.008 0.010"/>
    <axis xyz="0 0 1"/>
    <limit effort="10.6" lower="-1.570796327" upper="1.570796327" velocity="3.14"/>
    <!-- <limit velocity="3.14" effort="100" lower="-3" upper="3" /> -->
    <mimic joint="gripper_joint" multiplier="-1"/>
    <dynamics damping="0.1" friction="0.0"/>
    <implicitSpringDamper>True</implicitSpringDamper>
  </joint>
  <!-- <xacro:insert_transmission name="r_finger_passive_joint" /> -->
  <link name="r_truss_arm_link">
    <collision>
      <origin rpy="0.00 0.00 0.00" xyz="0.00 0.00 0.00"/>
      <geometry>
        <mesh filename="package://acroba_resources/meshes/rg2/collision/RG2_RightTrussArm_col.STL"/>
      </geometry>
    </collision>
    <visual>
      <origin rpy="0.00 0.00 0.00" xyz="0.00 0.00 0.00"/>
      <geometry>
        <mesh filename="package://acroba_resources/meshes/rg2/visual/RG2_RightTrussArm_vis.STL"/>
      </geometry>
    </visual>
    <inertial>
      <origin rpy="0.00 0.00 0.00" xyz="0.023075 -0.012136 -0.010000"/>
      <mass value="0.065927"/>
      <inertia ixx="0.000010" ixy="-0.000010" ixz="0.000000" iyy="0.000024" iyz="0.000000" izz="0.000025"/>
    </inertial>
  </link>
  <disable_collision link1="r_truss_arm_link" link2="l_truss_arm_link"/>
  <disable_collision link1="r_moment_arm_link" link2="l_moment_arm_link"/>
  <disable_collision link1="l_moment_arm_link" link2="r_truss_arm_link"/>
  <disable_collision link1="r_moment_arm_link" link2="l_truss_arm_link"/>
  <disable_collision link1="r_finger_link" link2="l_finger_link"/>
  <!-- Zivid Base Link -->
  <link name="base_camera">
    <!-- Visuals -->
    <visual>
      <origin rpy="1.5707963267948966 0 1.5707963267948966" xyz="-0.0030 -0.0758 0.0445"/>
      <material name="blue">
        <color rgba="0.25 0.25 0.25 1"/>
      </material>
      <geometry>
        <mesh filename="package://acroba_resources/meshes/sensors/zivid_one_plus/visual/zivid_one_plus.stl" scale="0.001 0.001 0.001"/>
      </geometry>
    </visual>
    <!-- Collisions -->
    <collision>
      <origin rpy="1.5707963267948966 0 1.5707963267948966" xyz="-0.0030 -0.0758 0.0445"/>
      <geometry>
        <mesh filename="package://acroba_resources/meshes/sensors/zivid_one_plus/collision/zivid_one_plus.stl" scale="0.001 0.001 0.001"/>
      </geometry>
    </collision>
    <!-- Inertia-->
    <inertial>
      <origin rpy="0 0 0" xyz="-0.00936000000 -0.00003000000 -0.00273000000"/>
      <mass value="2"/>
      <inertia ixx="0.00000429247" ixy="0.00000000000" ixz="0.00000002565" iyy="0.00000008027" iyz="0.00000000000" izz="0.00000427339"/>
    </inertial>
  </link>
  <!-- Zivid Optical (Measurement) and Projector Frames -->
  <link name="optical_frame"/>
  <link name="projector_frame"/>
  <!-- Zivid Optical (Measurement) and Projector Joints -->
  <joint name="optical_joint" type="fixed">
    <origin rpy="-1.5707963267948966 0 -1.7191493132144147" xyz="0.065 0.062 0.0445"/>
    <parent link="base_camera"/>
    <child link="optical_frame"/>
  </joint>
  <joint name="projector_joint" type="fixed">
    <origin rpy="-1.5707963267948966 0 -1.5707963267948966" xyz="-0.0030 -0.0758 0.0445"/>
    <parent link="base_camera"/>
    <child link="projector_frame"/>
  </joint>
  <!--joint for the gazebo plugin-->
  <link name="gazebo_cam_link"/>
  <joint name="gazebo_joint" type="fixed">
    <origin rpy="1.5707963267948966 -1.5707963267948966 0" xyz="0.0 0.0 0.0"/>
    <parent link="optical_frame"/>
    <child link="gazebo_cam_link"/>
  </joint>
  <!-- camera body, with origin at bottom screw mount -->
  <joint name="realsense_joint" type="fixed">
    <origin rpy="0.0 0.4647812 0" xyz="-0.1889999955892563 -0.6474999785423279 1.906630039215088"/>
    <parent link="world"/>
    <child link="realsense_bottom_screw_frame"/>
  </joint>
  <link name="realsense_bottom_screw_frame"/>
  <joint name="realsense_link_joint" type="fixed">
    <origin rpy="0 0 0" xyz="0.010600000000000002 0.0175 0.0125"/>
    <parent link="realsense_bottom_screw_frame"/>
    <child link="realsense_link"/>
  </joint>
  <link name="realsense_link">
    <visual>
      <!-- the mesh origin is at front plate in between the two infrared camera axes -->
      <origin rpy="1.5707963267948966 0 1.5707963267948966" xyz="0.0043 -0.0175 0"/>
      <geometry>
        <mesh filename="package://acroba_resources/meshes/realsense/d435.dae"/>
      </geometry>
    </visual>
    <collision>
      <origin rpy="0 0 0" xyz="0 -0.0175 0"/>
      <geometry>
        <box size="0.02505 0.09 0.025"/>
      </geometry>
    </collision>
    <inertial>
      <!-- The following are not reliable values, and should not be used for modeling -->
      <mass value="0.072"/>
      <origin xyz="0 0 0"/>
      <inertia ixx="0.003881243" ixy="0.0" ixz="0.0" iyy="0.000498940" iyz="0.0" izz="0.003879257"/>
    </inertial>
  </link>
  <!-- camera depth joints and links -->
  <joint name="realsense_depth_joint" type="fixed">
    <origin rpy="0 0 0" xyz="0 0 0"/>
    <parent link="realsense_link"/>
    <child link="realsense_depth_frame"/>
  </joint>
  <link name="realsense_depth_frame"/>
  <joint name="realsense_depth_optical_joint" type="fixed">
    <origin rpy="-1.5707963267948966 0 -1.5707963267948966" xyz="0 0 0"/>
    <parent link="realsense_depth_frame"/>
    <child link="realsense_depth_optical_frame"/>
  </joint>
  <link name="realsense_depth_optical_frame"/>
  <!-- camera left IR joints and links -->
  <joint name="realsense_infra1_joint" type="fixed">
    <origin rpy="0 0 0" xyz="0 0.0 0"/>
    <parent link="realsense_link"/>
    <child link="realsense_infra1_frame"/>
  </joint>
  <link name="realsense_infra1_frame"/>
  <joint name="realsense_infra1_optical_joint" type="fixed">
    <origin rpy="-1.5707963267948966 0 -1.5707963267948966" xyz="0 0 0"/>
    <parent link="realsense_infra1_frame"/>
    <child link="realsense_infra1_optical_frame"/>
  </joint>
  <link name="realsense_infra1_optical_frame"/>
  <!-- camera right IR joints and links -->
  <joint name="realsense_infra2_joint" type="fixed">
    <origin rpy="0 0 0" xyz="0 -0.05 0"/>
    <parent link="realsense_link"/>
    <child link="realsense_infra2_frame"/>
  </joint>
  <link name="realsense_infra2_frame"/>
  <joint name="realsense_infra2_optical_joint" type="fixed">
    <origin rpy="-1.5707963267948966 0 -1.5707963267948966" xyz="0 0 0"/>
    <parent link="realsense_infra2_frame"/>
    <child link="realsense_infra2_optical_frame"/>
  </joint>
  <link name="realsense_infra2_optical_frame"/>
  <!-- camera color joints and links -->
  <joint name="realsense_color_joint" type="fixed">
    <origin rpy="0 0 0" xyz="0 0.015 0"/>
    <parent link="realsense_link"/>
    <child link="realsense_color_frame"/>
  </joint>
  <link name="realsense_color_frame"/>
  <joint name="realsense_color_optical_joint" type="fixed">
    <origin rpy="-1.5707963267948966 0 -1.5707963267948966" xyz="0 0 0"/>
    <parent link="realsense_color_frame"/>
    <child link="realsense_color_optical_frame"/>
  </joint>
  <link name="realsense_color_optical_frame"/>
  <link name="smartshift">
    <visual>
      <origin rpy="0 0 0" xyz="0 0 0"/>
      <geometry>
        <mesh filename="package://acroba_resources/meshes/IMR_cell/smartshift2_rotated.dae" scale="1 1 1"/>
      </geometry>
    </visual>
    <collision>
      <origin rpy="0 0 0" xyz="0 0 0"/>
      <geometry>
        <mesh filename="package://acroba_resources/meshes/IMR_cell/smartshift2_rotated.dae" scale="1 1 1"/>
      </geometry>
    </collision>
  </link>
  <joint name="shift_joint" type="fixed">
    <parent link="tool0"/>
    <child link="smartshift"/>
    <origin rpy="0.0 0.0 3.141592" xyz="0.0 0.0 0.0"/>
  </joint>
  <joint name="shift_tool_joint" type="fixed">
    <parent link="smartshift"/>
    <child link="base_tool"/>
    <origin rpy="0.0 0.0 0.0" xyz="0.0 0.0 0.0908"/>
  </joint>
  <link name="imr_cell">
    <visual>
      <origin rpy="0 0 0" xyz="0 0 0"/>
      <geometry>
        <mesh filename="package://acroba_resources/meshes/IMR_cell/imr_cell_visual_inspection.dae"/>
      </geometry>
      <material name="cell">
        <color rgba="0.5 0.5 0.5 1.0"/>
      </material>
    </visual>
    <collision>
      <origin rpy="0 0 0" xyz="0 0 0"/>
      <geometry>
        <mesh filename="package://acroba_resources/meshes/IMR_cell/imr_cell_collision_inspection.dae"/>
      </geometry>
    </collision>
  </link>
  <link name="world"/>
  <joint name="world_cell" type="fixed">
    <parent link="world"/>
    <child link="imr_cell"/>
    <origin rpy="0 0 0" xyz="0.0 0.0 0.0"/>
  </joint>
  <joint name="imr_base_joint" type="fixed">
    <parent link="world"/>
    <child link="base_link"/>
    <origin rpy="0 0 0" xyz="0.163 -0.72 0.845"/>
  </joint>
  <joint name="camera_joint" type="fixed">
    <parent link="smartshift"/>
    <child link="base_camera"/>
    <origin rpy="-1.57079632679 -1.57079632679 0" xyz="-0.007223 0.067194 0.123316"/>
  </joint>
</robot>

