<?xml version="1.0" ?>
<!-- =================================================================================== -->
<!-- |    This document was autogenerated by xacro from industrial_cell.xacro          | -->
<!-- |    EDITING THIS FILE BY HAND IS NOT RECOMMENDED                                 | -->
<!-- =================================================================================== -->
<robot name="kr3_egp50">
  <!-- colours based on RAL values given in "FAQ - Colours of robot and robot
       controller", version "KUKA.Tifs | 2010-01-21 |YM| DefaultColorsRobotAndController.doc",
       downloaded 2015-07-18 from
       http://www.kuka.be/main/cservice/faqs/hardware/DefaultColorsRobotAndController.pdf

       all RAL colours converted using http://www.visual-graphics.de/en/customer-care/ral-colours
  -->
  <link name="base_link">
    <visual>
      <origin rpy="0 0 0" xyz="0 0 0"/>
      <geometry>
        <mesh filename="package://acroba_resources/meshes/kr3r540/visual/base_link.stl"/>
      </geometry>
      <material name="">
        <color rgba="0.5058823529411764 0.47058823529411764 0.38823529411764707 1.0"/>
      </material>
    </visual>
    <collision>
      <origin rpy="0 0 0" xyz="0 0 0"/>
      <geometry>
        <mesh filename="package://acroba_resources/meshes/kr3r540/collision/base_link.stl"/>
      </geometry>
    </collision>
  </link>
  <link name="link_1">
    <visual>
      <origin rpy="0 0 0" xyz="0 0 0"/>
      <geometry>
        <mesh filename="package://acroba_resources/meshes/kr3r540/visual/link_1.stl"/>
      </geometry>
      <material name="">
        <color rgba="0.9450980392156862 0.9254901960784314 1.0 1.0"/>
      </material>
    </visual>
    <collision>
      <origin rpy="0 0 0" xyz="0 0 0"/>
      <geometry>
        <mesh filename="package://acroba_resources/meshes/kr3r540/collision/link_1.stl"/>
      </geometry>
    </collision>
  </link>
  <link name="link_2">
    <visual>
      <origin rpy="0 0 0" xyz="0 0 0"/>
      <geometry>
        <mesh filename="package://acroba_resources/meshes/kr3r540/visual/link_2.stl"/>
      </geometry>
      <material name="">
        <color rgba="0.9450980392156862 0.9254901960784314 1.0 1.0"/>
      </material>
    </visual>
    <collision>
      <origin rpy="0 0 0" xyz="0 0 0"/>
      <geometry>
        <mesh filename="package://acroba_resources/meshes/kr3r540/collision/link_2.stl"/>
      </geometry>
    </collision>
  </link>
  <link name="link_3">
    <visual>
      <origin rpy="0 0 0" xyz="0 0 0"/>
      <geometry>
        <mesh filename="package://acroba_resources/meshes/kr3r540/visual/link_3.stl"/>
      </geometry>
      <material name="">
        <color rgba="0.9450980392156862 0.9254901960784314 1.0 1.0"/>
      </material>
    </visual>
    <collision>
      <origin rpy="0 0 0" xyz="0 0 0"/>
      <geometry>
        <mesh filename="package://acroba_resources/meshes/kr3r540/collision/link_3.stl"/>
      </geometry>
    </collision>
  </link>
  <link name="link_4">
    <visual>
      <origin rpy="0 0 0" xyz="0 0 0"/>
      <geometry>
        <mesh filename="package://acroba_resources/meshes/kr3r540/visual/link_4.stl"/>
      </geometry>
      <material name="">
        <color rgba="0.9450980392156862 0.9254901960784314 1.0 1.0"/>
      </material>
    </visual>
    <collision>
      <origin rpy="0 0 0" xyz="0 0 0"/>
      <geometry>
        <mesh filename="package://acroba_resources/meshes/kr3r540/collision/link_4.stl"/>
      </geometry>
    </collision>
  </link>
  <link name="link_5">
    <visual>
      <origin rpy="0 0 0" xyz="0 0 0"/>
      <geometry>
        <mesh filename="package://acroba_resources/meshes/kr3r540/visual/link_5.stl"/>
      </geometry>
      <material name="">
        <color rgba="0.9450980392156862 0.9254901960784314 1.0 1.0"/>
      </material>
    </visual>
    <collision>
      <origin rpy="0 0 0" xyz="0 0 0"/>
      <geometry>
        <mesh filename="package://acroba_resources/meshes/kr3r540/collision/link_5.stl"/>
      </geometry>
    </collision>
  </link>
  <link name="link_6">
    <visual>
      <origin rpy="0 0 0" xyz="0 0 0"/>
      <geometry>
        <mesh filename="package://acroba_resources/meshes/kr3r540/visual/link_6.stl"/>
      </geometry>
      <material name="">
        <color rgba="0.5058823529411764 0.47058823529411764 0.38823529411764707 1.0"/>
      </material>
    </visual>
    <collision>
      <origin rpy="0 0 0" xyz="0 0 0"/>
      <geometry>
        <mesh filename="package://acroba_resources/meshes/kr3r540/collision/link_6.stl"/>
      </geometry>
    </collision>
  </link>
  <!-- Following REP199, this frame shall be use to attach EEF or other equipment -->
  <link name="flange"/>
  <joint name="joint_a1" type="revolute">
    <origin rpy="0 0 0" xyz="0 0 0.345"/>
    <parent link="base_link"/>
    <child link="link_1"/>
    <axis xyz="0 0 -1"/>
    <limit effort="0" lower="-2.9670597283903604" upper="2.9670597283903604" velocity="9.250245035569947"/>
  </joint>
  <joint name="joint_a2" type="revolute">
    <origin rpy="0 0 0" xyz="0.020 0 0"/>
    <parent link="link_1"/>
    <child link="link_2"/>
    <axis xyz="0 1 0"/>
    <limit effort="0" lower="-2.9670597283903604" upper="0.8726646259971648" velocity="9.232791743050003"/>
  </joint>
  <joint name="joint_a3" type="revolute">
    <origin rpy="0 0 0" xyz="0.260 0 0"/>
    <parent link="link_2"/>
    <child link="link_3"/>
    <axis xyz="0 1 0"/>
    <limit effort="0" lower="-1.9198621771937625" upper="2.705260340591211" velocity="9.389871375729493"/>
  </joint>
  <joint name="joint_a4" type="revolute">
    <origin rpy="0 0 0" xyz="0 0 0.020"/>
    <parent link="link_3"/>
    <child link="link_4"/>
    <axis xyz="-1 0 0"/>
    <limit effort="0" lower="-3.0543261909900767" upper="3.0543261909900767" velocity="10.471975511965978"/>
  </joint>
  <joint name="joint_a5" type="revolute">
    <origin rpy="0 0 0" xyz="0.260 0 0"/>
    <parent link="link_4"/>
    <child link="link_5"/>
    <axis xyz="0 1 0"/>
    <limit effort="0" lower="-2.0943951023931953" upper="2.0943951023931953" velocity="10.471975511965978"/>
  </joint>
  <joint name="joint_a6" type="revolute">
    <origin rpy="0 0 0" xyz="0.075 0 0"/>
    <parent link="link_5"/>
    <child link="link_6"/>
    <axis xyz="-1 0 0"/>
    <limit effort="0" lower="-6.1086523819801535" upper="6.1086523819801535" velocity="13.962634015954636"/>
  </joint>
  <joint name="joint_a6-tool0" type="fixed">
    <parent link="link_6"/>
    <child link="flange"/>
    <origin rpy="0 0 0" xyz="0 0 0"/>
  </joint>
  <!-- ROS base_link to KUKA $ROBROOT coordinate system transform -->
  <link name="base"/>
  <joint name="base_link-base" type="fixed">
    <origin rpy="0 0 0" xyz="0 0 0"/>
    <parent link="base_link"/>
    <child link="base"/>
  </joint>
  <!-- This frame corresponds to the $TOOL coordinate system in KUKA KRC controllers -->
  <link name="tool0"/>
  <joint name="flange-tool0" type="fixed">
    <parent link="flange"/>
    <child link="tool0"/>
    <origin rpy="0 1.5707963267948966 0" xyz="0 0 0"/>
  </joint>
  <material name="schunk_dark_grey">
    <color rgba="0.3 0.3 0.3 1.0"/>
  </material>
  <material name="schunk_grey">
    <color rgba="0.8 0.8 0.8 1.0"/>
  </material>
  <link name="base_tool"/>
  <link name="tool_plate">
    <visual>
      <origin rpy="0 0 0" xyz="0 0 0.0"/>
      <geometry>
        <mesh filename="package://acroba_resources/meshes/schunk_EGP50/visual/schunk_plate.stl"/>
      </geometry>
      <material name="schunk_grey"/>
    </visual>
    <collision>
      <origin rpy="0 0 0" xyz="0 0 -0.0145"/>
      <geometry>
        <cylinder length="0.013" radius="0.04"/>
      </geometry>
    </collision>
  </link>
  <link name="tool_adaptor">
    <visual>
      <origin rpy="0 0 0" xyz="0 0 0.0"/>
      <geometry>
        <mesh filename="package://acroba_resources/meshes/schunk_EGP50/visual/schunk_adaptor.stl"/>
      </geometry>
      <material name="schunk_grey"/>
    </visual>
    <collision>
      <origin rpy="0 0 0" xyz="0 0 -0.004"/>
      <geometry>
        <box size="0.03 0.07 0.008"/>
      </geometry>
    </collision>
  </link>
  <link name="tool_body">
    <visual>
      <origin rpy="0 0 0" xyz="0 0 0.0"/>
      <geometry>
        <mesh filename="package://acroba_resources/meshes/schunk_EGP50/visual/schunk_body_scaled.stl"/>
      </geometry>
      <material name="schunk_grey"/>
    </visual>
    <collision>
      <origin rpy="0 0 0" xyz="0 0 0.0522"/>
      <geometry>
        <box size="0.03 0.0508 0.104"/>
      </geometry>
    </collision>
  </link>
  <link name="_left_base_finger">
    <visual>
      <origin rpy="0 0 0" xyz="0 0 0.0"/>
      <geometry>
        <mesh filename="package://acroba_resources/meshes/schunk_EGP50/visual/schunk_left_finger_base_scaled.stl"/>
      </geometry>
      <material name="schunk_dark_grey"/>
    </visual>
    <collision>
      <origin rpy="0 0 0" xyz="0.0 -0.021 0.11"/>
      <geometry>
        <box size="0.0195 0.008 0.014"/>
      </geometry>
    </collision>
  </link>
  <link name="_right_base_finger">
    <visual>
      <origin rpy="0 0 0" xyz="0 0 0.0"/>
      <geometry>
        <mesh filename="package://acroba_resources/meshes/schunk_EGP50/visual/schunk_right_finger_base_scaled.stl"/>
      </geometry>
      <material name="schunk_dark_grey"/>
    </visual>
    <collision>
      <origin rpy="0 0 0" xyz="0.0 0.021 0.11"/>
      <geometry>
        <box size="0.0195 0.008 0.014"/>
      </geometry>
    </collision>
  </link>
  <link name="_left_adaptor_finger">
    <visual>
      <origin rpy="0 0 0" xyz="0 0 0.0"/>
      <geometry>
        <mesh filename="package://acroba_resources/meshes/schunk_EGP50/visual/schunk_left_adaptor_scaled.stl"/>
      </geometry>
      <material name="schunk_dark_grey"/>
    </visual>
    <collision>
      <origin rpy="0 0 0" xyz="0.0 -0.0264 0.1231"/>
      <geometry>
        <box size="0.017 0.026 0.036"/>
      </geometry>
    </collision>
  </link>
  <link name="_right_adaptor_finger">
    <visual>
      <origin rpy="0 0 0" xyz="0 0 0.0"/>
      <geometry>
        <mesh filename="package://acroba_resources/meshes/schunk_EGP50/visual/schunk_right_adaptor_scaled.stl"/>
      </geometry>
      <material name="schunk_dark_grey"/>
    </visual>
    <collision>
      <origin rpy="0 0 0" xyz="0.0 0.0264 0.1231"/>
      <geometry>
        <box size="0.017 0.026 0.036"/>
      </geometry>
    </collision>
  </link>
  <link name="_left_visual_finger_tip">
    <visual>
      <origin rpy="0 0 0" xyz="0 0 0.0"/>
      <geometry>
        <mesh filename="package://acroba_resources/meshes/schunk_EGP50/visual/schunk_left_tip_visual.stl"/>
      </geometry>
      <material name="schunk_dark_grey"/>
    </visual>
    <collision>
      <origin rpy="0 0 0" xyz="0.0 -0.029 0.1505"/>
      <geometry>
        <box size="0.012 0.004 0.019"/>
      </geometry>
    </collision>
  </link>
  <link name="_right_visual_finger_tip">
    <visual>
      <origin rpy="0 0 0" xyz="0 0 0.0"/>
      <geometry>
        <mesh filename="package://acroba_resources/meshes/schunk_EGP50/visual/schunk_right_tip_visual.stl"/>
      </geometry>
      <material name="schunk_dark_grey"/>
    </visual>
    <collision>
      <origin rpy="0 0 0" xyz="0.0 0.029 0.1505"/>
      <geometry>
        <box size="0.012 0.004 0.019"/>
      </geometry>
    </collision>
  </link>
  <link name="_right_collision_finger_tip">
    <collision>
      <origin rpy="1.5707 0 0" xyz="0.0 0.0265 0.153"/>
      <geometry>
        <cylinder length="0.017" radius="0.005"/>
      </geometry>
    </collision>
  </link>
  <link name="_left_collision_finger_tip">
    <collision>
      <origin rpy="1.5707 0 0" xyz="0.0 -0.0266 0.153"/>
      <geometry>
        <cylinder length="0.017" radius="0.005"/>
      </geometry>
    </collision>
  </link>
  <joint name="_tool_base_plate" type="fixed">
    <origin rpy="0 0 0" xyz="0 0 0.018"/>
    <parent link="base_tool"/>
    <child link="tool_plate"/>
  </joint>
  <joint name="_tool_plate_adaptor" type="fixed">
    <origin rpy="0 0 0" xyz="0 0 0.0"/>
    <parent link="tool_plate"/>
    <child link="tool_adaptor"/>
  </joint>
  <joint name="_tool_adaptor_body" type="fixed">
    <origin rpy="0 0 0" xyz="0 0 0.0"/>
    <parent link="tool_adaptor"/>
    <child link="tool_body"/>
  </joint>
  <joint name="_left_finger_base_joint" type="prismatic">
    <origin rpy="0 0 0" xyz="0 0 0.0"/>
    <parent link="tool_body"/>
    <child link="_left_base_finger"/>
    <axis xyz="0 1 0"/>
    <limit effort="215" lower="0" upper="0.008" velocity="10"/>
  </joint>
  <joint name="_right_finger_base_joint" type="prismatic">
    <origin rpy="0 0 0" xyz="0 0 0.0"/>
    <parent link="tool_body"/>
    <child link="_right_base_finger"/>
    <axis xyz="0 -1 0"/>
    <limit effort="215" lower="0" upper="0.008" velocity="10"/>
  </joint>
  <joint name="_left_base_adaptor_joint" type="fixed">
    <origin rpy="0 0 0" xyz="0 0 0.0"/>
    <parent link="_left_base_finger"/>
    <child link="_left_adaptor_finger"/>
  </joint>
  <joint name="_right_base_adaptor_joint" type="fixed">
    <origin rpy="0 0 0" xyz="0 0 0.0"/>
    <parent link="_right_base_finger"/>
    <child link="_right_adaptor_finger"/>
  </joint>
  <joint name="_left_adaptor_vis_joint" type="fixed">
    <origin rpy="0 0 0" xyz="0 0 0.0"/>
    <parent link="_left_adaptor_finger"/>
    <child link="_left_visual_finger_tip"/>
  </joint>
  <joint name="_right_adaptor_vis_joint" type="fixed">
    <origin rpy="0 0 0" xyz="0 0 0.0"/>
    <parent link="_right_adaptor_finger"/>
    <child link="_right_visual_finger_tip"/>
  </joint>
  <joint name="_right_vis_col_joint" type="fixed">
    <origin rpy="0 0 0" xyz="0 0 0.0"/>
    <parent link="_right_visual_finger_tip"/>
    <child link="_right_collision_finger_tip"/>
  </joint>
  <joint name="_left_vis_col_joint" type="fixed">
    <origin rpy="0 0 0" xyz="0 0 0.0"/>
    <parent link="_left_visual_finger_tip"/>
    <child link="_left_collision_finger_tip"/>
  </joint>
  <link name="world"/>
  <joint name="world_joint" type="fixed">
    <parent link="world"/>
    <child link="base_link"/>
    <origin rpy="0.0 0.0 0.0" xyz="0 0 0"/>
  </joint>
  <joint name="tool_joint" type="fixed">
    <parent link="tool0"/>
    <child link="base_tool"/>
    <origin rpy="0.0 0.0 3.141592" xyz="0.0 0.0 0.0"/>
  </joint>
  <!-- Disabling collision between tool and robot, maybe not necessary-->
  <disable_collision link1="link_6" link2="tool_body"/>
</robot>
