<?xml version="1.0" ?>
<!-- =================================================================================== -->
<!-- |    This document was autogenerated by xacro from /home/VICOMTECH/mojer/catkin_ws/src/acroba_ros/acroba_resources/urdf/pgc140.xacro | -->
<!-- |    EDITING THIS FILE BY HAND IS NOT RECOMMENDED                                 | -->
<!-- =================================================================================== -->
<robot name="pgc140">
  <material name="pgc_dark_grey">
    <color rgba="0.3 0.3 0.3 1.0"/>
  </material>
  <material name="pgc_grey">
    <color rgba="0.45 0.45 0.45 1.0"/>
  </material>
  <!-- 0.6s openning time-->
  <!-- Finger and body intersect for 1.3mm this is taking into account in finger_length-->
  <link name="base_tool">
    <visual>
      <origin rpy="0 0 0" xyz="0.0 0.0 0.0"/>
      <geometry>
        <mesh filename="package://acroba_resources/meshes/pgc140/body_centered.dae" scale="0.001 0.001 0.001"/>
      </geometry>
      <material name="pgc_grey"/>
    </visual>
    <collision>
      <origin rpy="0 0 0" xyz="0.0 0.0 0.0"/>
      <geometry>
        <mesh filename="package://acroba_resources/meshes/pgc140/body_centered.dae" scale="0.001 0.001 0.001"/>
      </geometry>
    </collision>
    <inertial>
      <mass value="1"/>
      <inertia ixx="0.001151" ixy="0.0" ixz="0.0" iyy="0.001151" iyz="0.0" izz="0.000117"/>
    </inertial>
  </link>
  <link name="base_finger_1">
    <visual>
      <origin rpy="0 0 0" xyz="0.0 0.0 0.0"/>
      <geometry>
        <mesh filename="package://acroba_resources/meshes/pgc140/finger_holder_1_centered.dae" scale="0.001 0.001 0.001"/>
      </geometry>
      <material name="pgc_dark_grey"/>
    </visual>
    <collision>
      <origin rpy="0 0 0" xyz="0.0 0.0 0.0"/>
      <geometry>
        <mesh filename="package://acroba_resources/meshes/pgc140/finger_holder_1_centered.dae" scale="0.001 0.001 0.001"/>
      </geometry>
    </collision>
    <inertial>
      <mass value="0.05"/>
      <inertia ixx="0.00037" ixy="0.0" ixz="0.0" iyy="0.00037" iyz="0.0" izz="0.000146"/>
    </inertial>
  </link>
  <link name="base_finger_2">
    <visual>
      <origin rpy="0 0 0" xyz="0.0 0.0 0.0"/>
      <geometry>
        <mesh filename="package://acroba_resources/meshes/pgc140/finger_holder_2_centered.dae" scale="0.001 0.001 0.001"/>
      </geometry>
      <material name="pgc_dark_grey"/>
    </visual>
    <collision>
      <origin rpy="0 0 0" xyz="0.0 0.0 0.0"/>
      <geometry>
        <mesh filename="package://acroba_resources/meshes/pgc140/finger_holder_2_centered.dae" scale="0.001 0.001 0.001"/>
      </geometry>
    </collision>
    <inertial>
      <mass value="0.05"/>
      <inertia ixx="0.00037" ixy="0.0" ixz="0.0" iyy="0.00037" iyz="0.0" izz="0.000146"/>
    </inertial>
  </link>
  <link name="finger_1">
    <visual>
      <origin rpy="0.0 0.0 0.0" xyz="0 0 0.02025"/>
      <geometry>
        <box size="0.0115 0.017 0.0405"/>
      </geometry>
      <material name="pgc_dark_grey"/>
    </visual>
    <collision>
      <origin rpy="0.0 0.0 0.0" xyz="0 0 0.02025"/>
      <geometry>
        <box size="0.0115 0.017 0.0405"/>
      </geometry>
    </collision>
    <inertial>
      <mass value="0.1"/>
      <inertia ixx="0.00037" ixy="0.0" ixz="0.0" iyy="0.00037" iyz="0.0" izz="0.000146"/>
    </inertial>
  </link>
  <link name="finger_2">
    <visual>
      <origin rpy="0.0 0.0 0.0" xyz="0 0 0.02025"/>
      <geometry>
        <box size="0.0115 0.017 0.0405"/>
      </geometry>
      <material name="pgc_dark_grey"/>
    </visual>
    <collision>
      <origin rpy="0.0 0.0 0.0" xyz="0 0 0.02025"/>
      <geometry>
        <box size="0.0115 0.017 0.0405"/>
      </geometry>
    </collision>
    <inertial>
      <mass value="1"/>
      <inertia ixx="0.00037" ixy="0.0" ixz="0.0" iyy="0.00037" iyz="0.0" izz="0.000146"/>
    </inertial>
  </link>
  <joint name="joint_base_finger_1" type="prismatic">
    <origin rpy="0 0 0" xyz="0 0 0"/>
    <parent link="base_tool"/>
    <child link="base_finger_1"/>
    <axis xyz="-1 0 0"/>
    <limit effort="140" lower="0" upper="0.025" velocity="0.04166666666666667"/>
  </joint>
  <joint name="joint_base_finger_2" type="prismatic">
    <origin rpy="0 0 0" xyz="0 0 0"/>
    <parent link="base_tool"/>
    <child link="base_finger_2"/>
    <axis xyz="1 0 0"/>
    <limit effort="140" lower="0" upper="0.025" velocity="0.04166666666666667"/>
  </joint>
  <joint name="joint_finger_1" type="fixed">
    <origin rpy="0 0 0" xyz="0.03075 0 0.0915"/>
    <parent link="base_finger_1"/>
    <child link="finger_1"/>
  </joint>
  <joint name="joint_finger_2" type="fixed">
    <origin rpy="0 0 0" xyz="-0.03075 0  0.0915"/>
    <parent link="base_finger_2"/>
    <child link="finger_2"/>
  </joint>
  --&gt;

  
  <link name="gripping_point"/>
  <joint name="joint_gripping" type="fixed">
    <origin rpy="0 0 0" xyz="0. 0 0.132"/>
    <parent link="base_tool"/>
    <child link="gripping_point"/>
  </joint>
  <!-- Add gazebo colors-->
  <gazebo reference="base_tool">
    <material>Gazebo/FlatBlack</material>
  </gazebo>
  <gazebo reference="base_finger_1">
    <material>Gazebo/FlatBlack</material>
  </gazebo>
  <gazebo reference="base_finger_2">
    <material>Gazebo/FlatBlack</material>
  </gazebo>
  <gazebo reference="finger_1">
    <material>Gazebo/FlatBlack</material>
  </gazebo>
  <gazebo reference="finger_2">
    <material>Gazebo/FlatBlack</material>
  </gazebo>
  <!-- Transmissions-->
  <transmission name="joint_finger1_trans">
    <type>transmission_interface/SimpleTransmission</type>
    <joint name="joint_base_finger_1">
      <hardwareInterface>hardware_interface/EffortJointInterface</hardwareInterface>
    </joint>
    <actuator name="joint_base_finger_1_motor">
      <hardwareInterface>hardware_interface/EffortJointInterface</hardwareInterface>
      <mechanicalReduction>1</mechanicalReduction>
    </actuator>
  </transmission>
  <transmission name="joint_finger2_trans">
    <type>transmission_interface/SimpleTransmission</type>
    <joint name="joint_base_finger_2">
      <hardwareInterface>hardware_interface/EffortJointInterface</hardwareInterface>
    </joint>
    <actuator name="joint_base_finger_2_motor">
      <hardwareInterface>hardware_interface/EffortJointInterface</hardwareInterface>
      <mechanicalReduction>1</mechanicalReduction>
    </actuator>
  </transmission>
  <disable_collision link1="wrist_3_link" link2="base_tool">
  </disable_collision>
  <!-- Disabling collision for gripper-->
  <disable_collision link1="base_tool" link2="base_finger_1">
  </disable_collision>
  <disable_collision link1="base_tool" link2="base_finger_2">
  </disable_collision>
  <disable_collision link1="base_finger_2" link2="base_finger_1">
  </disable_collision>
  <disable_collision link1="base_tool" link2="finger_1">
  </disable_collision>
  <disable_collision link1="base_tool" link2="finger_2">
  </disable_collision>
  <disable_collision link1="base_finger_2" link2="finger_2">
  </disable_collision>
  <disable_collision link1="base_finger_1" link2="finger_1">
  </disable_collision>
  <link name="world"/>
  <joint name="world" type="fixed">
    <origin rpy="0 0 0" xyz="0 0 0"/>
    <parent link="world"/>
    <child link="base_tool"/>
  </joint>
  <gazebo>
    <plugin filename="libgazebo_ros_control.so" name="gazebo_ros_control">
      </plugin>
  </gazebo>
</robot>
