<?xml version="1.0" ?>
<!-- =================================================================================== -->
<!-- |    This document was autogenerated by xacro from /home/mojer/catkin_ws/src/acroba_ros/acroba_resources/urdf/pgc50.xacro | -->
<!-- |    EDITING THIS FILE BY HAND IS NOT RECOMMENDED                                 | -->
<!-- =================================================================================== -->
<robot name="pgc50">
  <material name="pgc_dark_grey">
    <color rgba="0.3 0.3 0.3 1.0"/>
  </material>
  <material name="pgc_grey">
    <color rgba="0.45 0.45 0.45 1.0"/>
  </material>
  <!-- Finger and body intersect for 1.3mm this is taking into account in finger_length-->
  <link name="base_body">
    <visual>
      <origin rpy="0 0 0" xyz="0.0 0.0 0.0"/>
      <geometry>
        <mesh filename="package://acroba_resources/meshes/pgc50/body.stl" scale="0.001 0.001 0.001"/>
      </geometry>
      <material name="pgc_grey"/>
    </visual>
    <collision>
      <origin rpy="0 0 0" xyz="0.0 0.0 0.0"/>
      <geometry>
        <mesh filename="package://acroba_resources/meshes/pgc50/body.stl" scale="0.001 0.001 0.001"/>
      </geometry>
    </collision>
    <inertial>
      <mass value="0.5"/>
      <inertia ixx="0.0037" ixy="0.0" ixz="0.0" iyy="0.0037" iyz="0.0" izz="0.0146"/>
    </inertial>
  </link>
  <link name="base_finger_1">
    <visual>
      <origin rpy="0 0 0" xyz="0.0 0.0 0.0"/>
      <geometry>
        <mesh filename="package://acroba_resources/meshes/pgc50/finger_holder_1.stl" scale="0.001 0.001 0.001"/>
      </geometry>
      <material name="pgc_dark_grey"/>
    </visual>
    <collision>
      <origin rpy="0 0 0" xyz="0.0 0.0 0.0"/>
      <geometry>
        <mesh filename="package://acroba_resources/meshes/pgc50/finger_holder_1.stl" scale="0.001 0.001 0.001"/>
      </geometry>
    </collision>
    <inertial>
      <mass value="0.05"/>
      <inertia ixx="0.0037" ixy="0.0" ixz="0.0" iyy="0.0037" iyz="0.0" izz="0.0146"/>
    </inertial>
  </link>
  <link name="base_finger_2">
    <visual>
      <origin rpy="0 0 0" xyz="0.0 0.0 0.0"/>
      <geometry>
        <mesh filename="package://acroba_resources/meshes/pgc50/finger_holder_2.stl" scale="0.001 0.001 0.001"/>
      </geometry>
      <material name="pgc_dark_grey"/>
    </visual>
    <collision>
      <origin rpy="0 0 0" xyz="0.0 0.0 0.0"/>
      <geometry>
        <mesh filename="package://acroba_resources/meshes/pgc50/finger_holder_2.stl" scale="0.001 0.001 0.001"/>
      </geometry>
    </collision>
    <inertial>
      <mass value="0.05"/>
      <inertia ixx="0.0037" ixy="0.0" ixz="0.0" iyy="0.0037" iyz="0.0" izz="0.0146"/>
    </inertial>
  </link>
  <link name="finger_1">
    <visual>
      <origin rpy="0.0 0.0 0.0" xyz="0 0 0"/>
      <geometry>
        <mesh filename="package://acroba_resources/meshes/pgc50/finger_1.stl" scale="0.001 0.001 0.001"/>
      </geometry>
      <material name="pgc_dark_grey"/>
    </visual>
    <collision>
      <origin rpy="0.0 0.0 0.0" xyz="0 0 0"/>
      <geometry>
        <mesh filename="package://acroba_resources/meshes/pgc50/finger_1.stl" scale="0.001 0.001 0.001"/>
      </geometry>
    </collision>
    <inertial>
      <mass value="0.1"/>
      <inertia ixx="0.0037" ixy="0.0" ixz="0.0" iyy="0.0037" iyz="0.0" izz="0.0146"/>
    </inertial>
  </link>
  <link name="finger_2">
    <visual>
      <origin rpy="0.0 0.0 0.0" xyz="0 0 0"/>
      <geometry>
        <mesh filename="package://acroba_resources/meshes/pgc50/finger_2.stl" scale="0.001 0.001 0.001"/>
      </geometry>
      <material name="pgc_dark_grey"/>
    </visual>
    <collision>
      <origin rpy="0.0 0.0 0.0" xyz="0 0 0"/>
      <geometry>
        <mesh filename="package://acroba_resources/meshes/pgc50/finger_2.stl" scale="0.001 0.001 0.001"/>
      </geometry>
    </collision>
    <inertial>
      <mass value="0.1"/>
      <inertia ixx="0.0037" ixy="0.0" ixz="0.0" iyy="0.0037" iyz="0.0" izz="0.0146"/>
    </inertial>
  </link>
  <joint name="joint_base_finger_1" type="prismatic">
    <origin rpy="0 0 0" xyz="0 0 0"/>
    <parent link="base_body"/>
    <child link="base_finger_1"/>
    <axis xyz="1 0 0"/>
    <limit effort="50" lower="0" upper="0.0175" velocity="10"/>
  </joint>
  <joint name="joint_base_finger_2" type="prismatic">
    <origin rpy="0 0 0" xyz="0 0 0"/>
    <parent link="base_body"/>
    <child link="base_finger_2"/>
    <axis xyz="-1 0 0"/>
    <limit effort="50" lower="0" upper="0.0175" velocity="10"/>
  </joint>
  <joint name="joint_finger_1" type="fixed">
    <origin rpy="0 0 0" xyz="0 0 0"/>
    <parent link="base_finger_1"/>
    <child link="finger_1"/>
  </joint>
  <joint name="joint_finger_2" type="fixed">
    <origin rpy="0 0 0" xyz="0 0 0"/>
    <parent link="base_finger_2"/>
    <child link="finger_2"/>
  </joint>
  <link name="gripping_point"/>
  <joint name="joint_gripping" type="fixed">
    <origin rpy="0 0 0" xyz="0. 0 0.1242"/>
    <parent link="base_body"/>
    <child link="gripping_point"/>
  </joint>
</robot>
