<?xml version="1.0" encoding="utf-8"?>
<!-- =================================================================================== -->
<!-- |    This document was autogenerated by xacro from C:\catkin_ws\src\acroba_ros\acroba_resources\urdf\rosmal_cell.xacro | -->
<!-- |    EDITING THIS FILE BY HAND IS NOT RECOMMENDED                                 | -->
<!-- =================================================================================== -->
<robot name="rosmal_cell">
  <link name="base_link">
    <visual>
      <geometry>
        <mesh filename="package://acroba_resources/meshes/ur10/visual/base.dae"/>
      </geometry>
      <material name="LightGrey">
        <color rgba="0.7 0.7 0.7 1.0"/>
      </material>
    </visual>
    <collision>
      <geometry>
        <mesh filename="package://acroba_resources/meshes/ur10/collision/base.stl"/>
      </geometry>
    </collision>
    <inertial>
      <mass value="4.0"/>
      <origin rpy="0 0 0" xyz="0.0 0.0 0.0"/>
      <inertia ixx="0.0061063308908" ixy="0.0" ixz="0.0" iyy="0.0061063308908" iyz="0.0" izz="0.01125"/>
    </inertial>
  </link>
  <joint name="shoulder_pan_joint" type="revolute">
    <parent link="base_link"/>
    <child link="shoulder_link"/>
    <origin rpy="0.0 0.0 0.0" xyz="0.0 0.0 0.1273"/>
    <axis xyz="0 0 1"/>
    <limit effort="330.0" lower="-6.283185307179586" upper="6.283185307179586" velocity="2.16"/>
    <dynamics damping="0.0" friction="0.0"/>
  </joint>
  <link name="shoulder_link">
    <visual>
      <geometry>
        <mesh filename="package://acroba_resources/meshes/ur10/visual/shoulder.dae"/>
      </geometry>
      <material name="LightGrey">
        <color rgba="0.7 0.7 0.7 1.0"/>
      </material>
    </visual>
    <collision>
      <geometry>
        <mesh filename="package://acroba_resources/meshes/ur10/collision/shoulder.stl"/>
      </geometry>
    </collision>
    <inertial>
      <mass value="7.778"/>
      <origin rpy="0 0 0" xyz="0.0 0.0 0.0"/>
      <inertia ixx="0.03147431257693659" ixy="0.0" ixz="0.0" iyy="0.03147431257693659" iyz="0.0" izz="0.021875624999999996"/>
    </inertial>
  </link>
  <joint name="shoulder_lift_joint" type="revolute">
    <parent link="shoulder_link"/>
    <child link="upper_arm_link"/>
    <origin rpy="0.0 1.5707963267948966 0.0" xyz="0.0 0.220941 0.0"/>
    <axis xyz="0 1 0"/>
    <limit effort="330.0" lower="-6.283185307179586" upper="6.283185307179586" velocity="2.16"/>
    <dynamics damping="0.0" friction="0.0"/>
  </joint>
  <link name="upper_arm_link">
    <visual>
      <geometry>
        <mesh filename="package://acroba_resources/meshes/ur10/visual/upperarm.dae"/>
      </geometry>
      <material name="LightGrey">
        <color rgba="0.7 0.7 0.7 1.0"/>
      </material>
    </visual>
    <collision>
      <geometry>
        <mesh filename="package://acroba_resources/meshes/ur10/collision/upperarm.stl"/>
      </geometry>
    </collision>
    <inertial>
      <mass value="12.93"/>
      <origin rpy="0 0 0" xyz="0.0 -0.045 0.306"/>
      <inertia ixx="0.42175380379841093" ixy="0.0" ixz="0.0" iyy="0.42175380379841093" iyz="0.0" izz="0.03636562499999999"/>
    </inertial>
  </link>
  <joint name="elbow_joint" type="revolute">
    <parent link="upper_arm_link"/>
    <child link="forearm_link"/>
    <origin rpy="0.0 0.0 0.0" xyz="0.0 -0.1719 0.612"/>
    <axis xyz="0 1 0"/>
    <limit effort="150.0" lower="-3.141592653589793" upper="3.141592653589793" velocity="3.15"/>
    <dynamics damping="0.0" friction="0.0"/>
  </joint>
  <link name="forearm_link">
    <visual>
      <geometry>
        <mesh filename="package://acroba_resources/meshes/ur10/visual/forearm.dae"/>
      </geometry>
      <material name="LightGrey">
        <color rgba="0.7 0.7 0.7 1.0"/>
      </material>
    </visual>
    <collision>
      <geometry>
        <mesh filename="package://acroba_resources/meshes/ur10/collision/forearm.stl"/>
      </geometry>
    </collision>
    <inertial>
      <mass value="3.87"/>
      <origin rpy="0 0 0" xyz="0.0 0.0 0.28615"/>
      <inertia ixx="0.11106969409710458" ixy="0.0" ixz="0.0" iyy="0.11106969409710458" iyz="0.0" izz="0.010884375"/>
    </inertial>
  </link>
  <joint name="wrist_1_joint" type="revolute">
    <parent link="forearm_link"/>
    <child link="wrist_1_link"/>
    <origin rpy="0.0 1.5707963267948966 0.0" xyz="0.0 0.0 0.5723"/>
    <axis xyz="0 1 0"/>
    <limit effort="54.0" lower="-6.283185307179586" upper="6.283185307179586" velocity="3.2"/>
    <dynamics damping="0.0" friction="0.0"/>
  </joint>
  <link name="wrist_1_link">
    <visual>
      <geometry>
        <mesh filename="package://acroba_resources/meshes/ur10/visual/wrist1.dae"/>
      </geometry>
      <material name="LightGrey">
        <color rgba="0.7 0.7 0.7 1.0"/>
      </material>
    </visual>
    <collision>
      <geometry>
        <mesh filename="package://acroba_resources/meshes/ur10/collision/wrist1.stl"/>
      </geometry>
    </collision>
    <inertial>
      <mass value="1.96"/>
      <origin rpy="0 0 0" xyz="0.0 0.1149 0.0"/>
      <inertia ixx="0.005108247956699999" ixy="0.0" ixz="0.0" iyy="0.005108247956699999" iyz="0.0" izz="0.005512499999999999"/>
    </inertial>
  </link>
  <joint name="wrist_2_joint" type="revolute">
    <parent link="wrist_1_link"/>
    <child link="wrist_2_link"/>
    <origin rpy="0.0 0.0 0.0" xyz="0.0 0.1149 0.0"/>
    <axis xyz="0 0 1"/>
    <limit effort="54.0" lower="-6.283185307179586" upper="6.283185307179586" velocity="3.2"/>
    <dynamics damping="0.0" friction="0.0"/>
  </joint>
  <link name="wrist_2_link">
    <visual>
      <geometry>
        <mesh filename="package://acroba_resources/meshes/ur10/visual/wrist2.dae"/>
      </geometry>
      <material name="LightGrey">
        <color rgba="0.7 0.7 0.7 1.0"/>
      </material>
    </visual>
    <collision>
      <geometry>
        <mesh filename="package://acroba_resources/meshes/ur10/collision/wrist2.stl"/>
      </geometry>
    </collision>
    <inertial>
      <mass value="1.96"/>
      <origin rpy="0 0 0" xyz="0.0 0.0 0.1157"/>
      <inertia ixx="0.005108247956699999" ixy="0.0" ixz="0.0" iyy="0.005108247956699999" iyz="0.0" izz="0.005512499999999999"/>
    </inertial>
  </link>
  <joint name="wrist_3_joint" type="revolute">
    <parent link="wrist_2_link"/>
    <child link="wrist_3_link"/>
    <origin rpy="0.0 0.0 0.0" xyz="0.0 0.0 0.1157"/>
    <axis xyz="0 1 0"/>
    <limit effort="54.0" lower="-6.283185307179586" upper="6.283185307179586" velocity="3.2"/>
    <dynamics damping="0.0" friction="0.0"/>
  </joint>
  <link name="wrist_3_link">
    <visual>
      <geometry>
        <mesh filename="package://acroba_resources/meshes/ur10/visual/wrist3.dae"/>
      </geometry>
      <material name="LightGrey">
        <color rgba="0.7 0.7 0.7 1.0"/>
      </material>
    </visual>
    <collision>
      <geometry>
        <mesh filename="package://acroba_resources/meshes/ur10/collision/wrist3.stl"/>
      </geometry>
    </collision>
    <inertial>
      <mass value="0.202"/>
      <origin rpy="1.5707963267948966 0 0" xyz="0.0 0.07695 0.0"/>
      <inertia ixx="0.00011792166116465" ixy="0.0" ixz="0.0" iyy="0.00011792166116465" iyz="0.0" izz="0.00020452500000000002"/>
    </inertial>
  </link>
  <joint name="ee_fixed_joint" type="fixed">
    <parent link="wrist_3_link"/>
    <child link="ee_link"/>
    <origin rpy="0.0 0.0 1.5707963267948966" xyz="0.0 0.0922 0.0"/>
  </joint>
  <link name="ee_link">
    <collision>
      <geometry>
        <box size="0.01 0.01 0.01"/>
      </geometry>
      <origin rpy="0 0 0" xyz="-0.01 0 0"/>
    </collision>
  </link>
  <transmission name="shoulder_pan_trans">
    <type>transmission_interface/SimpleTransmission</type>
    <joint name="shoulder_pan_joint">
      <hardwareInterface>hardware_interface/PositionJointInterface</hardwareInterface>
    </joint>
    <actuator name="shoulder_pan_motor">
      <mechanicalReduction>1</mechanicalReduction>
    </actuator>
  </transmission>
  <transmission name="shoulder_lift_trans">
    <type>transmission_interface/SimpleTransmission</type>
    <joint name="shoulder_lift_joint">
      <hardwareInterface>hardware_interface/PositionJointInterface</hardwareInterface>
    </joint>
    <actuator name="shoulder_lift_motor">
      <mechanicalReduction>1</mechanicalReduction>
    </actuator>
  </transmission>
  <transmission name="elbow_trans">
    <type>transmission_interface/SimpleTransmission</type>
    <joint name="elbow_joint">
      <hardwareInterface>hardware_interface/PositionJointInterface</hardwareInterface>
    </joint>
    <actuator name="elbow_motor">
      <mechanicalReduction>1</mechanicalReduction>
    </actuator>
  </transmission>
  <transmission name="wrist_1_trans">
    <type>transmission_interface/SimpleTransmission</type>
    <joint name="wrist_1_joint">
      <hardwareInterface>hardware_interface/PositionJointInterface</hardwareInterface>
    </joint>
    <actuator name="wrist_1_motor">
      <mechanicalReduction>1</mechanicalReduction>
    </actuator>
  </transmission>
  <transmission name="wrist_2_trans">
    <type>transmission_interface/SimpleTransmission</type>
    <joint name="wrist_2_joint">
      <hardwareInterface>hardware_interface/PositionJointInterface</hardwareInterface>
    </joint>
    <actuator name="wrist_2_motor">
      <mechanicalReduction>1</mechanicalReduction>
    </actuator>
  </transmission>
  <transmission name="wrist_3_trans">
    <type>transmission_interface/SimpleTransmission</type>
    <joint name="wrist_3_joint">
      <hardwareInterface>hardware_interface/PositionJointInterface</hardwareInterface>
    </joint>
    <actuator name="wrist_3_motor">
      <mechanicalReduction>1</mechanicalReduction>
    </actuator>
  </transmission>
  <gazebo reference="shoulder_link">
    <selfCollide>true</selfCollide>
  </gazebo>
  <gazebo reference="upper_arm_link">
    <selfCollide>true</selfCollide>
  </gazebo>
  <gazebo reference="forearm_link">
    <selfCollide>true</selfCollide>
  </gazebo>
  <gazebo reference="wrist_1_link">
    <selfCollide>true</selfCollide>
  </gazebo>
  <gazebo reference="wrist_3_link">
    <selfCollide>true</selfCollide>
  </gazebo>
  <gazebo reference="wrist_2_link">
    <selfCollide>true</selfCollide>
  </gazebo>
  <gazebo reference="ee_link">
    <selfCollide>true</selfCollide>
  </gazebo>
  <!-- ROS base_link to UR 'Base' Coordinates transform -->
  <link name="base"/>
  <joint name="base_link-base_fixed_joint" type="fixed">
    <!-- NOTE: this rotation is only needed as long as base_link itself is
                 not corrected wrt the real robot (ie: rotated over 180
                 degrees)
      -->
    <origin rpy="0 0 -3.141592653589793" xyz="0 0 0"/>
    <parent link="base_link"/>
    <child link="base"/>
  </joint>
  <!-- Frame coincident with all-zeros TCP on UR controller -->
  <link name="tool0"/>
  <joint name="wrist_3_link-tool0_fixed_joint" type="fixed">
    <origin rpy="-1.5707963267948966 0 0" xyz="0 0.0922 0"/>
    <parent link="wrist_3_link"/>
    <child link="tool0"/>
  </joint>
  <link name="extension_base">
    <visual>
      <origin rpy="0 0 0" xyz="0.0 0.0 0.0"/>
      <geometry>
        <mesh filename="package://acroba_resources/meshes/miscellaneous/rosmal/extension_camera.stl"/>
      </geometry>
      <material name="Grey">
        <color rgba="0.5 0.5 0.5 1.0"/>
      </material>
    </visual>
    <collision>
      <origin rpy="0 0 0" xyz="0.0 0.0 0.0"/>
      <geometry>
        <mesh filename="package://acroba_resources/meshes/miscellaneous/rosmal/extension_camera.stl"/>
      </geometry>
    </collision>
    <inertial>
      <mass value="0.2"/>
      <origin rpy="0 0 0" xyz="0.0 0.0 0.0"/>
      <inertia ixx="0.000190679090395" ixy="0.0" ixz="0.0" iyy="0.000190679090395" iyz="0.0" izz="9.9225e-05"/>
    </inertial>
  </link>
  <link name="extension">
    <visual>
      <origin rpy="0 0 0" xyz="0.0 0.0 0.0"/>
      <geometry>
        <mesh filename="package://acroba_resources/meshes/miscellaneous/rosmal/gripper_extension.stl"/>
      </geometry>
      <material name="Grey">
        <color rgba="0.5 0.5 0.5 1.0"/>
      </material>
    </visual>
    <collision>
      <origin rpy="0 0 0" xyz="0.0 0.0 0.046"/>
      <geometry>
        <cylinder length="0.092" radius="0.0315"/>
      </geometry>
    </collision>
    <inertial>
      <mass value="0.2"/>
      <origin rpy="0 0 0" xyz="0.0 0.0 0.0"/>
      <inertia ixx="0.000190679090395" ixy="0.0" ixz="0.0" iyy="0.000190679090395" iyz="0.0" izz="9.9225e-05"/>
    </inertial>
  </link>
  <link name="extension_top">
    <visual>
      <origin rpy="0 0 0" xyz="0.0 0.0 0.01"/>
      <geometry>
        <mesh filename="package://acroba_resources/meshes/miscellaneous/rosmal/gripper_extension_top.stl"/>
      </geometry>
      <material name="Grey">
        <color rgba="0.5 0.5 0.5 1.0"/>
      </material>
    </visual>
    <collision>
      <origin rpy="0 0 0" xyz="0.0 0.0 0.005"/>
      <geometry>
        <cylinder length="0.01" radius="0.0315"/>
      </geometry>
    </collision>
    <inertial>
      <mass value="0.2"/>
      <origin rpy="0 0 0" xyz="0.0 0.0 0.0"/>
      <inertia ixx="0.000190679090395" ixy="0.0" ixz="0.0" iyy="0.000190679090395" iyz="0.0" izz="9.9225e-05"/>
    </inertial>
  </link>
  <joint name="joint_extension_camera" type="fixed">
    <parent link="extension_base"/>
    <child link="extension"/>
    <origin rpy="0.0 0.0 0.0" xyz="0.0 0.0 0.01"/>
  </joint>
  <joint name="joint_extensions" type="fixed">
    <parent link="extension"/>
    <child link="extension_top"/>
    <origin rpy="0.0 0.0 0.0" xyz="0.0 0.0 0.092"/>
  </joint>
  <link name="extension_tool0"/>
  <joint name="joint_extensiontool" type="fixed">
    <parent link="extension_top"/>
    <child link="extension_tool0"/>
    <origin rpy="0.0 0.0 0.0" xyz="0.0 0.0 0.01"/>
  </joint>
  <disable_collision link1="extension" link2="extension_top"/>
  <disable_collision link1="extension_camera" link2="extension"/>
  <material name="pgc_dark_grey">
    <color rgba="0.3 0.3 0.3 1.0"/>
  </material>
  <material name="pgc_grey">
    <color rgba="0.45 0.45 0.45 1.0"/>
  </material>
  <!-- 0.6s openning time-->
  <!-- Finger and body intersect for 1.3mm this is taking into account in finger_length-->
  <link name="base_tool">
    <visual>
      <origin rpy="0 0 0" xyz="0.0 0.0 0.0"/>
      <geometry>
        <mesh filename="package://acroba_resources/meshes/pgc140/body_centered.dae" scale="0.001 0.001 0.001"/>
      </geometry>
      <material name="pgc_grey"/>
    </visual>
    <collision>
      <origin rpy="0 0 0" xyz="0.0 0.0 0.0"/>
      <geometry>
        <mesh filename="package://acroba_resources/meshes/pgc140/body_centered.dae" scale="0.001 0.001 0.001"/>
      </geometry>
    </collision>
    <inertial>
      <mass value="1"/>
      <inertia ixx="0.001151" ixy="0.0" ixz="0.0" iyy="0.001151" iyz="0.0" izz="0.000117"/>
    </inertial>
  </link>
  <link name="base_finger_1">
    <visual>
      <origin rpy="0 0 0" xyz="0.0 0.0 0.0"/>
      <geometry>
        <mesh filename="package://acroba_resources/meshes/pgc140/finger_holder_1_centered.dae" scale="0.001 0.001 0.001"/>
      </geometry>
      <material name="pgc_dark_grey"/>
    </visual>
    <collision>
      <origin rpy="0 0 0" xyz="0.0 0.0 0.0"/>
      <geometry>
        <mesh filename="package://acroba_resources/meshes/pgc140/finger_holder_1_centered.dae" scale="0.001 0.001 0.001"/>
      </geometry>
    </collision>
    <inertial>
      <mass value="0.05"/>
      <inertia ixx="0.00037" ixy="0.0" ixz="0.0" iyy="0.00037" iyz="0.0" izz="0.000146"/>
    </inertial>
  </link>
  <link name="base_finger_2">
    <visual>
      <origin rpy="0 0 0" xyz="0.0 0.0 0.0"/>
      <geometry>
        <mesh filename="package://acroba_resources/meshes/pgc140/finger_holder_2_centered.dae" scale="0.001 0.001 0.001"/>
      </geometry>
      <material name="pgc_dark_grey"/>
    </visual>
    <collision>
      <origin rpy="0 0 0" xyz="0.0 0.0 0.0"/>
      <geometry>
        <mesh filename="package://acroba_resources/meshes/pgc140/finger_holder_2_centered.dae" scale="0.001 0.001 0.001"/>
      </geometry>
    </collision>
    <inertial>
      <mass value="0.05"/>
      <inertia ixx="0.00037" ixy="0.0" ixz="0.0" iyy="0.00037" iyz="0.0" izz="0.000146"/>
    </inertial>
  </link>
  <link name="finger_1">
    <visual>
      <origin rpy="0.0 0.0 0.0" xyz="0 0 0.02025"/>
      <geometry>
        <box size="0.0115 0.017 0.0405"/>
      </geometry>
      <material name="pgc_dark_grey"/>
    </visual>
    <collision>
      <origin rpy="0.0 0.0 0.0" xyz="0 0 0.02025"/>
      <geometry>
        <box size="0.0115 0.017 0.0405"/>
      </geometry>
    </collision>
    <inertial>
      <mass value="0.1"/>
      <inertia ixx="0.00037" ixy="0.0" ixz="0.0" iyy="0.00037" iyz="0.0" izz="0.000146"/>
    </inertial>
  </link>
  <link name="finger_2">
    <visual>
      <origin rpy="0.0 0.0 0.0" xyz="0 0 0.02025"/>
      <geometry>
        <box size="0.0115 0.017 0.0405"/>
      </geometry>
      <material name="pgc_dark_grey"/>
    </visual>
    <collision>
      <origin rpy="0.0 0.0 0.0" xyz="0 0 0.02025"/>
      <geometry>
        <box size="0.0115 0.017 0.0405"/>
      </geometry>
    </collision>
    <inertial>
      <mass value="1"/>
      <inertia ixx="0.00037" ixy="0.0" ixz="0.0" iyy="0.00037" iyz="0.0" izz="0.000146"/>
    </inertial>
  </link>
  <joint name="joint_base_finger_1" type="prismatic">
    <origin rpy="0 0 0" xyz="0 0 0"/>
    <parent link="base_tool"/>
    <child link="base_finger_1"/>
    <axis xyz="-1 0 0"/>
    <limit effort="140" lower="0" upper="0.025" velocity="0.0416666666667"/>
  </joint>
  <joint name="joint_base_finger_2" type="prismatic">
    <origin rpy="0 0 0" xyz="0 0 0"/>
    <parent link="base_tool"/>
    <child link="base_finger_2"/>
    <axis xyz="1 0 0"/>
    <limit effort="140" lower="0" upper="0.025" velocity="0.0416666666667"/>
  </joint>
  <joint name="joint_finger_1" type="fixed">
    <origin rpy="0 0 0" xyz="0.03075 0 0.0915"/>
    <parent link="base_finger_1"/>
    <child link="finger_1"/>
  </joint>
  <joint name="joint_finger_2" type="fixed">
    <origin rpy="0 0 0" xyz="-0.03075 0  0.0915"/>
    <parent link="base_finger_2"/>
    <child link="finger_2"/>
  </joint>
  --&gt;

  
  <link name="gripping_point"/>
  <joint name="joint_gripping" type="fixed">
    <origin rpy="0 0 0" xyz="0. 0 0.132"/>
    <parent link="base_tool"/>
    <child link="gripping_point"/>
  </joint>
  <!-- Add gazebo colors-->
  <gazebo reference="base_tool">
    <material>Gazebo/FlatBlack</material>
  </gazebo>
  <gazebo reference="base_finger_1">
    <material>Gazebo/FlatBlack</material>
  </gazebo>
  <gazebo reference="base_finger_2">
    <material>Gazebo/FlatBlack</material>
  </gazebo>
  <gazebo reference="finger_1">
    <material>Gazebo/FlatBlack</material>
  </gazebo>
  <gazebo reference="finger_2">
    <material>Gazebo/FlatBlack</material>
  </gazebo>
  <!-- Transmissions-->
  <transmission name="joint_finger1_trans">
    <type>transmission_interface/SimpleTransmission</type>
    <joint name="joint_base_finger_1">
      <hardwareInterface>hardware_interface/EffortJointInterface</hardwareInterface>
    </joint>
    <actuator name="joint_base_finger_1_motor">
      <hardwareInterface>hardware_interface/EffortJointInterface</hardwareInterface>
      <mechanicalReduction>1</mechanicalReduction>
    </actuator>
  </transmission>
  <transmission name="joint_finger2_trans">
    <type>transmission_interface/SimpleTransmission</type>
    <joint name="joint_base_finger_2">
      <hardwareInterface>hardware_interface/EffortJointInterface</hardwareInterface>
    </joint>
    <actuator name="joint_base_finger_2_motor">
      <hardwareInterface>hardware_interface/EffortJointInterface</hardwareInterface>
      <mechanicalReduction>1</mechanicalReduction>
    </actuator>
  </transmission>
  <disable_collision link1="wrist_3_link" link2="base_tool">
  </disable_collision>
  <!-- Disabling collision for gripper-->
  <disable_collision link1="base_tool" link2="base_finger_1">
  </disable_collision>
  <disable_collision link1="base_tool" link2="base_finger_2">
  </disable_collision>
  <disable_collision link1="base_finger_2" link2="base_finger_1">
  </disable_collision>
  <disable_collision link1="base_tool" link2="finger_1">
  </disable_collision>
  <disable_collision link1="base_tool" link2="finger_2">
  </disable_collision>
  <disable_collision link1="base_finger_2" link2="finger_2">
  </disable_collision>
  <disable_collision link1="base_finger_1" link2="finger_1">
  </disable_collision>
  <link name="world"/>
  <joint name="world_joint" type="fixed">
    <parent link="world"/>
    <child link="base_link"/>
    <origin rpy="0 0 0" xyz="0 0 0"/>
  </joint>
  <joint name="tool_extension_joint" type="fixed">
    <parent link="tool0"/>
    <child link="extension_base"/>
    <origin rpy="0 0 0" xyz="0 0 0"/>
  </joint>
  <joint name="extension_gripper_joint" type="fixed">
    <parent link="extension_tool0"/>
    <child link="base_tool"/>
    <origin rpy="0 0 0" xyz="0 0 0"/>
  </joint>
</robot>
