<?xml version="1.0" ?>
<!-- =================================================================================== -->
<!-- |    This document was autogenerated by xacro from schunk_EGP50.xacro             | -->
<!-- |    EDITING THIS FILE BY HAND IS NOT RECOMMENDED                                 | -->
<!-- =================================================================================== -->
<robot name="schunk">
  <material name="schunk_dark_grey">
    <color rgba="0.3 0.3 0.3 1.0"/>
  </material>
  <material name="schunk_grey">
    <color rgba="0.8 0.8 0.8 .0"/>
  </material>
  <link name="base_tool"/>
  <link name="_body">
    <visual>
      <origin rpy="0 0 0" xyz="0 0 0.0"/>
      <geometry>
        <mesh filename="package://acroba_resources/meshes/schunk_EGP50/visual/schunk_body_scaled.stl"/>
      </geometry>
    </visual>
    <material name="schunk_grey"/>
    <collision>
      <origin rpy="0 0 0" xyz="0 0 0.0522"/>
      <geometry>
        <box size="0.03 0.0508 0.104"/>
      </geometry>
    </collision>
  </link>
  <link name="_left_base_finger">
    <visual>
      <origin rpy="0 0 0" xyz="0 0 0.0"/>
      <geometry>
        <mesh filename="package://acroba_resources/meshes/schunk_EGP50/visual/schunk_left_finger_base_scaled.stl"/>
      </geometry>
    </visual>
    <material name="schunk_dark_grey"/>
    <collision>
      <origin rpy="0 0 0" xyz="0.0 -0.021 0.11"/>
      <geometry>
        <box size="0.0195 0.008 0.014"/>
      </geometry>
    </collision>
  </link>
  <link name="_right_base_finger">
    <visual>
      <origin rpy="0 0 0" xyz="0 0 0.0"/>
      <geometry>
        <mesh filename="package://acroba_resources/meshes/schunk_EGP50/visual/schunk_right_finger_base_scaled.stl"/>
      </geometry>
    </visual>
    <material name="schunk_dark_grey"/>
    <collision>
      <origin rpy="0 0 0" xyz="0.0 0.021 0.11"/>
      <geometry>
        <box size="0.0195 0.008 0.014"/>
      </geometry>
    </collision>
  </link>
  <link name="_left_adaptor_finger">
    <visual>
      <origin rpy="0 0 0" xyz="0 0 0.0"/>
      <geometry>
        <mesh filename="package://acroba_resources/meshes/schunk_EGP50/visual/schunk_left_adaptor_scaled.stl"/>
      </geometry>
    </visual>
    <material name="schunk_dark_grey"/>
    <collision>
      <origin rpy="0 0 0" xyz="0.0 -0.0264 0.1231"/>
      <geometry>
        <box size="0.017 0.026 0.036"/>
      </geometry>
    </collision>
  </link>
  <link name="_right_adaptor_finger">
    <visual>
      <origin rpy="0 0 0" xyz="0 0 0.0"/>
      <geometry>
        <mesh filename="package://acroba_resources/meshes/schunk_EGP50/visual/schunk_right_adaptor_scaled.stl"/>
      </geometry>
    </visual>
    <material name="schunk_dark_grey"/>
    <collision>
      <origin rpy="0 0 0" xyz="0.0 0.0264 0.1231"/>
      <geometry>
        <box size="0.017 0.026 0.036"/>
      </geometry>
    </collision>
  </link>
  <link name="_left_visual_finger_tip">
    <visual>
      <origin rpy="0 0 0" xyz="0 0 0.0"/>
      <geometry>
        <mesh filename="package://acroba_resources/meshes/schunk_EGP50/visual/schunk_left_tip_visual.stl"/>
      </geometry>
    </visual>
    <material name="schunk_dark_grey"/>
    <collision>
      <origin rpy="0 0 0" xyz="0.0 -0.029 0.1505"/>
      <geometry>
        <box size="0.012 0.004 0.019"/>
      </geometry>
    </collision>
  </link>
  <link name="_right_visual_finger_tip">
    <visual>
      <origin rpy="0 0 0" xyz="0 0 0.0"/>
      <geometry>
        <mesh filename="package://acroba_resources/meshes/schunk_EGP50/visual/schunk_right_tip_visual.stl"/>
      </geometry>
    </visual>
    <material name="schunk_dark_grey"/>
    <collision>
      <origin rpy="0 0 0" xyz="0.0 0.029 0.1505"/>
      <geometry>
        <box size="0.012 0.004 0.019"/>
      </geometry>
    </collision>
  </link>
  <link name="_right_collision_finger_tip">
    <collision>
      <origin rpy="1.5707 0 0" xyz="0.0 0.0265 0.153"/>
      <geometry>
        <cylinder length="0.017" radius="0.005"/>
      </geometry>
    </collision>
  </link>
  <link name="_left_collision_finger_tip">
    <collision>
      <origin rpy="1.5707 0 0" xyz="0.0 -0.0266 0.153"/>
      <geometry>
        <cylinder length="0.017" radius="0.005"/>
      </geometry>
    </collision>
  </link>
  <joint name="_tool_base_joint" type="fixed">
    <origin rpy="0 0 0" xyz="0 0 0.0"/>
    <parent link="base_tool"/>
    <child link="_body"/>
  </joint>
  <joint name="_left_finger_base_joint" type="prismatic">
    <origin rpy="0 0 0" xyz="0 0 0.0"/>
    <parent link="_body"/>
    <child link="_left_base_finger"/>
    <axis xyz="0 1 0"/>
    <limit effort="215" lower="0" upper="0.008" velocity="10"/>
  </joint>
  <joint name="_right_finger_base_joint" type="prismatic">
    <origin rpy="0 0 0" xyz="0 0 0.0"/>
    <parent link="_body"/>
    <child link="_right_base_finger"/>
    <axis xyz="0 -1 0"/>
    <limit effort="215" lower="0" upper="0.008" velocity="10"/>
  </joint>
  <joint name="_left_base_adaptor_joint" type="fixed">
    <origin rpy="0 0 0" xyz="0 0 0.0"/>
    <parent link="_left_base_finger"/>
    <child link="_left_adaptor_finger"/>
  </joint>
  <joint name="_right_base_adaptor_joint" type="fixed">
    <origin rpy="0 0 0" xyz="0 0 0.0"/>
    <parent link="_right_base_finger"/>
    <child link="_right_adaptor_finger"/>
  </joint>
  <joint name="_left_adaptor_vis_joint" type="fixed">
    <origin rpy="0 0 0" xyz="0 0 0.0"/>
    <parent link="_left_adaptor_finger"/>
    <child link="_left_visual_finger_tip"/>
  </joint>
  <joint name="_right_adaptor_vis_joint" type="fixed">
    <origin rpy="0 0 0" xyz="0 0 0.0"/>
    <parent link="_right_adaptor_finger"/>
    <child link="_right_visual_finger_tip"/>
  </joint>
  <joint name="_right_vis_col_joint" type="fixed">
    <origin rpy="0 0 0" xyz="0 0 0.0"/>
    <parent link="_right_visual_finger_tip"/>
    <child link="_right_collision_finger_tip"/>
  </joint>
  <joint name="_left_vis_col_joint" type="fixed">
    <origin rpy="0 0 0" xyz="0 0 0.0"/>
    <parent link="_left_visual_finger_tip"/>
    <child link="_left_collision_finger_tip"/>
  </joint>
</robot>
